Workbook
Name \g: #N/A
Name \p: #N/A
Name \s: #N/A
Name ______MAR97: #REF!
Name ______SEC107: #REF!
Name _____MAR97: #REF!
Name _____SEC107: #REF!
Name ____MAR97: #REF!
Name ____SEC107: #REF!
Name ___MAR97: #REF!
Name ___SEC107: #REF!
Name __MAR97: #REF!
Name __SEC107: #REF!
Name _97: #REF!
Name _MAR96: #REF!
Name _MAR97: #REF!
Name _SEC107: #REF!
Name abc: Scheduled_Payment+Extra_Payment
Name Acc.Code: #REF!
Name AD._TO_EMP.: [7]PL!#REF!
Name ADJUSTMENTS: [7]PL!#REF!
Name ADV: [8]acct!#REF!
Name AICPA: #REF!
Name Amount: #REF!
Name ASSETS: [7]PL!#REF!
Name AUD_PLAN: [7]PL!#REF!
Name Automated: #REF!
Name B_SHEET: [7]PL!#REF!
Name Beg_Bal: #REF!
Name BHAKAKRI: #N/A
Name CH.IN.EQUIT: [8]acct!#REF!
Name cHECK: [8]acct!#REF!
Name chk: #REF!
Name CONTROL: #N/A
Name ControlType: #REF!
Name CRED: [8]acct!#REF!
Name Currency: #REF!
Name Data: #REF!
Name dEFF.LIA: [8]acct!#REF!
Name Description: #REF!
Name dhdhd: #N/A
Name End_Bal: #REF!
Name Extra_Pay: #REF!
Name FA: [8]acct!#REF!
Name FAROOQ: #N/A
Name fhfhf: #N/A
Name FINASSET: [8]acct!#REF!
Name Frequency: '[9]Drop down'!$C$6:$C$13
Name Full_Print: #REF!
Name Header_Row: ROW(#REF!)
Name Hyperlink_Inquiry: #REF!
Name Hyperlink_Inspection: #REF!
Name Hyperlink_Observation: #REF!
Name Hyperlink_PAE: #REF!
Name Hyperlink_Reperformance: #REF!
Name Hyperlink_Update: #REF!
Name Inquiry: #REF!
Name Inspection: #REF!
Name Int: #REF!
Name Interest_Rate: #REF!

Sheet Ratio analysis
F2: F O R M U L A | H2: 2023 | J2: =H2-1 -> 2022
B4: A. | D4: PROFITABILITY RATIOS
B6: 1 | D6: Gross Profit % to Net Sales | F6: Gross Profit/Net Sales X 100 | H6: =Working!G7 -> #DIV/0! | J6: =Working!I7 -> #DIV/0!
B8: 2 | D8: Net profit (Loss) percent of sales | F8: Net Profit / (Loss) before tax/ Sales X 100 | H8: =Working!G12 -> #DIV/0! | J8: =Working!I12 -> #DIV/0!
B10: 3 | D10: Return on assets (ROA) | F10: Net Profit after tax/ total assets | H10: =Working!G17 -> #DIV/0! | J10: =Working!I17 -> #DIV/0!
B12: 4 | D12: Return on Capital Employed (ROCE) | F12: Net Profit after tax/ total capital employed | H12: =Working!G22 -> #DIV/0! | J12: =Working!I22 -> #DIV/0!
B14: 5 | D14: Earning per share (EPS) (Rupees per share) | F14: Net profit available to equity holder/Number of ordinary shares outstanding | H14: =Working!G27 -> #DIV/0! | J14: =Working!I27 -> #DIV/0!
B16: B. | D16: ACTIVITY RATIOS
B18: 1 | D18: Raw Material Turnover | F18: Cost of raw material used/Avg. raw material inventory | H18: =Working!G34 -> #DIV/0! | J18: =Working!I34 -> #DIV/0!
B20: 2 | D20: Work in process turnover | F20: Cost of good manufactured/Avg. Work in process inventory | H20: =Working!G39 -> #DIV/0! | J20: =Working!I39 -> #DIV/0!
B22: 3 | D22: Finished goods turnover | F22: Cost of good sold/Avg. finished goods inventory | H22: =Working!G44 -> #DIV/0! | J22: =Working!I44 -> #DIV/0!
B24: 4 | D24: Debtor turnover | F24: Sales / Debtors | H24: =Working!G50 -> #DIV/0! | J24: =Working!I50 -> #DIV/0!
B26: 5 | D26: Creditors | F26: Purchases / Creditors | H26: =Working!G55 -> #DIV/0! | J26: =Working!I55 -> #DIV/0!
B28: 6 | D28: Fixed assets turnover | F28: Cost of goods sold/Average fixed assets | H28: =Working!G60 -> #DIV/0! | J28: =Working!I60 -> #DIV/0!
B30: 7 | D30: Working Capital turnover | F30: Cost of good sold/Net working capital | H30: =Working!G65 -> #DIV/0! | J30: =Working!I65 -> #DIV/0!
B32: C. | D32: EXPENSES TO SALES RATIOS
B34: 1 | D34: Administrative Expenses ratio | F34: Administrative Expenses/Net Sales | H34: =Working!G71 -> #DIV/0! | J34: =Working!I71 -> #DIV/0!
B36: 2 | D36: Selling Expenses ratio | F36: Selling Expenses/Net Sales | H36: =Working!G76 -> #DIV/0! | J36: =Working!I76 -> #DIV/0!
B38: 3 | D38: Financial Expenses ratio | F38: Financial Expenses/Net Sale | H38: =Working!G81 -> #DIV/0! | J38: =Working!I81 -> #DIV/0!
B40: D. | D40: LIQUIDITY RATIOS
B42: 1 | D42: Current Ratio | F42: Current assets/Current liabilities | H42: =Working!G88 -> #DIV/0! | J42: =Working!I88 -> #DIV/0!
B44: 2 | D44: Acid - Test quick ratio | F44: Quick assets/Current liabilities | H44: =Working!G93 -> #DIV/0! | J44: =Working!I93 -> #DIV/0!
B46: E. | D46: LEVERAGE / CAPITAL STRUCTURE RATIOS
B48: 1 | D48: Debt - Equity ratio | F48: Total debt/Share holders equity | H48: =Working!G100 -> #DIV/0! | J48: =Working!I100 -> #DIV/0!
B50: 2 | D50: Equity Turnover | F50: Sales/Net worth | H50: =Working!G105 -> #DIV/0! | J50: =Working!I105 -> #DIV/0!
B52: 3 | D52: Owner’s stake in the fixed assets | F52: Fixed assets/Net worth | H52: =Working!G110 -> #DIV/0! | J52: =Working!I110 -> #DIV/0!
B54: Conclusion:
B55: Based on above results, noting has come to our attention that could cause us to belive us otherwise.

Sheet Working
A1: WORKING FOR RATIO ANALYSIS
E3: Formula | G3: ='Ratio analysis'!H2 -> 2023 | I3: =G3-1 -> 2022
A5: PERFORMANCE ANALYSIS
A7: 1 | C7: Gross Profit % to Net Sales | E7: Gross Profit/Net Sales | G7: =+ROUND(G9/G10,2) -> #DIV/0! | I7: =+ROUND(I9/I10,2) -> #DIV/0!
C9: Gross Profit
C10: Net Sales
A12: 2 | C12: Net profit (Loss) percent of sales | E12: Net Profit / (Loss) / Sales X 100 | G12: =G14/G15 -> #DIV/0! | I12: =I14/I15 -> #DIV/0!
C14: Net Profit before tax
C15: Sales in Rupees( Net)
A17: 3 | C17: Return on assets (ROA) | E17: Net Profit after tax/ total assets x 100 | G17: =G19/G20 -> #DIV/0! | I17: =I19/I20 -> #DIV/0!
C19: Net Profit After tax
C20: Total Assets
A22: 4 | C22: Return on Capital Employed (ROCE) | E22: Net Profit after tax/ total capital employed x 100 | G22: =G24/G25 -> #DIV/0! | I22: =I24/I25 -> #DIV/0!
C24: Net Profit after tax
C25: Total capital employed
A27: 5 | C27: Earning per share (EPS) (Rupees per share) | E27: Net profit available to equity holder/Number of ordinary shares outstanding | G27: =G29/G30 -> #DIV/0! | I27: =I29/I30 -> #DIV/0!
C29: Net Profit Available to equity holder
C30: No. of ordinary shares
A32: C. | C32: ACTIVITY RATIOS
A34: 1 | C34: Raw Material Turnover | E34: Cost of raw material used/ Raw material inventory | G34: =G36/G37 -> #DIV/0! | I34: =I36/I37 -> #DIV/0!
C36: Raw material comnsumed
C37: Closing stock raw material
A39: 2 | C39: Work in process turnover | E39: Cost of goods manufactured/ Work in process inventory | G39: =G41/G42 -> #DIV/0! | I39: =I41/I42 -> #DIV/0!
C41: Cost of goods manufactured
C42: Closing w.i.p inventory
A44: 3 | C44: Finished goodss turnover | E44: Cost of goods sold / finished goodss inventory | G44: =G47/G48 -> #DIV/0! | I44: =I47/I48 -> #DIV/0!
C47: Cost of goods sold
C48: Closing Finished Goods stock
A50: 4 | C50: Debtor turnover | E50: Sales / Debtors | G50: =G52/G53 -> #DIV/0! | I50: =I52/I53 -> #DIV/0!
C52: Sales
C53: Debtors
A55: 5 | C55: Creditors turnover | E55: Purchases / Creditors | G55: =G57/G58 -> #DIV/0! | I55: =I57/I58 -> #DIV/0!
C57: Purchases
C58: Creditors
A60: 6 | C60: Fixed assets turnover | E60: Cost of goods sold/Average fixed assets | G60: =G62/G63 -> #DIV/0! | I60: =I62/I63 -> #DIV/0!
C62: Cost of Goods Sold
C63: Fixed Assets
A65: 7 | C65: Working Capital turnover | E65: Cost of goods sold / working capital | G65: =G67/G68 -> #DIV/0! | I65: =I67/I68 -> #DIV/0!
C67: Cost of Goods sold
C68: Working Capital
...
