Workbook

Sheet Cover
B1: Name of Company | C1: ABC LIMITED
B2: Reporting Date | C2: =UPPER("as at "&G6) -> AS AT JUNE 30, 2023
B3: Period under Audit | C3: =UPPER("for the year ended "&G6) -> FOR THE YEAR ENDED JUNE 30, 2023
B5: Basic Information | I5: Date Value
B6: Current year presented for year from and to? | E6: July 01, 2022 | G6: June 30, 2023 | H6: 2023 | I6: 44743 | J6: 45107
B7: Comparative information presented for year from and to? | E7: July 01, 2021 | G7: June 30, 2022 | H7: 2022 | I7: 44378 | J7: 44742
B8: Total notes provided in the financial statements from and to? | E8: =Policies!A5 -> 1 | G8: =Notes!A753 -> 38
B9: Signatories | E9: Chief Executive | G9: Director
B10: Authorized share capital Number of shares and value per share. | G10: 10
B11: Functional and Presentation Currency | E11: Rupees
B12: Applicable Financial Reporting Framework | E12: Revised AFRS for SSEs
B13: Measurement method? (Cost / Revaluation) | E13: Cost | I13: Cost | J13: Revaluation
I14: IFRSs | J14: International Financial Reporting Standards issued by the International Accounting Standards Board (IASB) as notified under the Companies Act, 2017; and
I15: IFRS for SMEs | J15: International Financial Reporting Standards for Small and Medium Sized Entities (IFRS for SMEs) issued by the International Accounting Standards Board (IASB) as notified under the Companies Act, 2017; and
I16: Revised AFRS for SSEs | J16: Revised Accounting and Financial Reporting Standards for Small Sized Entities (Revised AFRS for SSEs) issued by the Institute of Chartered Accountants of Pakistan (ICAP) as notified under the Companies Act, 2017; and
I17: AFRS for NPOs | J17: Accounting and Financial Reporting Standards for Non Government Organizations and Not for Profit Organization (AFRS for NPOs) issued by the Institute of Chartered Accountants of Pakistan (ICAP); and

Sheet SOFP
B1: =Cover!C1 -> ABC LIMITED
B2: STATEMENT OF FINANCIAL POSITION
B3: =Cover!C2 -> AS AT JUNE 30, 2023
J5: Note | L5: =Cover!H6 -> 2023 | N5: =Cover!H7 -> 2022
L6: ------------- Rupees -------------
B8: ASSETS
B9: Non-current assets
B10: Property, plant and equipment | J10: =Policies!A73+1 -> 5 | L10: =FAS!L11 -> 0 | N10: =FAS!N11 -> 0
B11: Investment properties | J11: =J10+1 -> 6 | L11: =Notes!L71 -> 0 | N11: =Notes!N71 -> 0
B12: Intangible assets | J12: =J11+1 -> 7 | L12: =Notes!L91 -> 0 | N12: =Notes!N91 -> 0
B13: Long-term loans and advances | J13: =J12+1 -> 8 | L13: =Notes!L105 -> 0 | N13: =Notes!N105 -> 0
B14: Deferred tax assets | J14: =J13+1 -> 9 | L14: =Notes!L143 -> 0 | N14: =Notes!N143 -> 0
L16: =SUM(L10:L15) -> 0 | N16: =SUM(N10:N15) -> 0
B18: Current assets
B19: Stores, spares and loose tools | J19: =J14+1 -> 10 | L19: 0 | N19: 0
B20: Inventories | J20: =J19+1 -> 11 | L20: =Notes!L178 -> 0 | N20: =Notes!N178 -> 0
B21: Trade receivables - net | J21: =J20+1 -> 12 | L21: =Notes!L184 -> 0 | N21: =Notes!N184 -> 0
B22: Advances, deposits and prepayments | J22: =J21+1 -> 13 | L22: =Notes!L197 -> 0 | N22: =Notes!N197 -> 0
B23: Tax refunds due from government | L23: 0 | N23: 0
B24: Cash and cash equivalents (excluding bank overdrafts) | J24: =J22+1 -> 14 | L24: =Notes!L208 -> 0 | N24: =Notes!N208 -> 0
L26: =SUM(L20:L25) -> 0 | N26: =SUM(N20:N25) -> 0
B28: Total assets | L28: =L16+L26 -> 0 | N28: =N16+N26 -> 0
B30: EQUITY AND LIABILITIES
B31: Share capital and reserves
B32: Authorized share capital | L32: =IFERROR(Cover!E10*Cover!G10,0) -> 0 | N32: =IFERROR(Cover!E10*Cover!G10,0) -> 0
B33: =TEXT(Cover!E10,"##,###")&" Ordinary shares of Rs. "&Cover!G10 &" each." -> Ordinary shares of Rs. 10 each.
B35: Issued, subscribed and paid up share capital | J35: =J24+1 -> 15 | L35: =Notes!L230 -> 0 | N35: =Notes!N230 -> 0
B36: Share deposit money | J36: =J35+1 -> 16 | L36: =Notes!L248 -> 0 | N36: =Notes!N248 -> 0
B37: Other reserves | J37: =J36+1 -> 17 | L37: =Notes!L262 -> 0 | N37: =Notes!N262 -> 0
B38: Retained earnings | L38: =SOCIE!N22 -> 0 | N38: =SOCIE!N14 -> 0
L40: =SUM(L35:L39) -> 0 | N40: =SUM(N35:N39) -> 0
B42: Non-current liabilities
B43: Borrowings | J43: =J37+1 -> 18 | L43: =Notes!L291 -> 0 | N43: =Notes!N291 -> 0
B44: Deferred tax liabilities | J44: =J14 -> 9 | L44: 0 | N44: 0
L46: =SUM(L43:L45) -> 0 | N46: =SUM(N43:N45) -> 0
B48: Current liabilities
B49: Trade and other payables | J49: =J43+1 -> 19 | L49: =Notes!L329 -> 0 | N49: =Notes!N329 -> 0
B50: ="Current portion of "&LOWER(B43) -> Current portion of borrowings | J50: =J43 -> 18 | L50: =Notes!L290 -> 0 | N50: =Notes!N290 -> 0
B51: Payable to related parties | J51: =J49+1 -> 20 | L51: =Notes!L335 -> 0 | N51: =Notes!N335 -> 0
B52: Deferred revenue | J52: =J51+1 -> 21
...

Sheet SOPL
B1: =Cover!C1 -> ABC LIMITED
B2: STATEMENT OF PROFIT OR LOSS
B3: =Cover!C3 -> FOR THE YEAR ENDED JUNE 30, 2023
J5: =SOFP!J5 -> Note | L5: =SOFP!L5 -> 2023 | N5: =SOFP!N5 -> 2022
L6: =SOFP!L6 -> ------------- Rupees -------------
B8: Revenue - net | J8: =SOFP!J57+1 -> 23 | L8: =Notes!L416 -> 0 | N8: =Notes!N416 -> 0
B10: Cost of revenue | J10: =J8+1 -> 24 | L10: =-Notes!L424 -> 0 | N10: =-Notes!N424 -> 0
B12: =IF(AND(L12>=0,N12>=0),"Gross profit",IF(AND(L12>=0,N12<0),"Gross profit / (loss)",IF(AND(L12<0,N12>=0),"Gross (loss) / profit","Gross loss"))) -> Gross profit | L12: =SUM(L8:L11) -> 0 | N12: =SUM(N8:N11) -> 0
B14: Distribution costs | J14: =J10+1 -> 25 | L14: =-Notes!L516 -> 0 | N14: =-Notes!N516 -> 0
B15: Administrative expenses | J15: =J14+1 -> 26 | L15: =-Notes!L531 -> 0 | N15: =-Notes!N531 -> 0
B16: Other operating income / (expenses) | J16: =J15+1 -> 27 | L16: =-Notes!L564 -> 0 | N16: =-Notes!N564 -> 0
B17: Other gains/(losses) | J17: =J16+1 -> 28 | L17: =-Notes!L599 -> 0 | N17: =-Notes!N599 -> 0
L19: =SUM(L14:L18) -> 0 | N19: =SUM(N14:N18) -> 0
B21: =IF(AND(L21>=0,N21>=0),"Operating profit",IF(AND(L21>=0,N21<0),"Operating profit / (loss)",IF(AND(L21<0,N21>=0),"Operating (loss) / profit","Operating loss"))) -> Operating profit | L21: =L12+L19 -> 0 | N21: =N12+N19 -> 0
B23: Other income | J23: =J17+1 -> 29 | L23: =Notes!L606 -> 0 | N23: =Notes!N606 -> 0
B24: Finance costs | J24: =J23+1 -> 30 | L24: =-Notes!L619 -> 0 | N24: =-Notes!N619 -> 0
L26: =SUM(L23:L24) -> 0 | N26: =SUM(N23:N24) -> 0
B28: =IF(AND(L28>=0,N28>=0),"Profit before tax",IF(AND(L28>=0,N28<0),"Profit / (loss) before tax",IF(AND(L28<0,N28>=0),"(Loss) / profit before tax","Loss before tax"))) -> Profit before tax | L28: =L21+L26 -> 0 | N28: =N21+N26 -> 0
B30: Taxation | J30: =J24+1 -> 31 | L30: =-Notes!L627 -> 0 | N30: =-Notes!N627 -> 0
B32: =IF(AND(L32>=0,N32>=0),"Profit after tax",IF(AND(L32>=0,N32<0),"Profit / (loss) after tax",IF(AND(L32<0,N32>=0),"(Loss) / profit after tax","Loss after tax"))) -> Profit after tax | L32: =SUM(L28:L31) -> 0 | N32: =SUM(N28:N31) -> 0
B34: Earnings per share - basic | J34: =J30+1 -> 32 | L34: =Notes!#REF! -> #REF! | N34: =Notes!#REF! -> #REF!
B36: =SOFP!B63 -> The annexed notes from 1 to 38 form an integral part of these financial statements.
B42: =SOFP!B69 -> Chief Executive | L42: =SOFP!L69 -> Director

Sheet SOCI
B1: =Cover!C1 -> ABC LIMITED
B2: STATEMENT OF COMPREHENSIVE INCOME
B3: =Cover!C3 -> FOR THE YEAR ENDED JUNE 30, 2023
J5: =SOFP!J5 -> Note | L5: =SOFP!L5 -> 2023 | N5: =SOFP!N5 -> 2022
L6: =SOFP!L6 -> ------------- Rupees -------------
B8: =SOPL!B32 -> Profit after tax | L8: =SOPL!L32 -> 0 | N8: =SOPL!N32 -> 0
B10: Other comprehensive income
B12: Items that may be subsequently reclassified to profit or loss
B13: Changes in the fair value of available-for-sale financial assets
B14: Exchange differences on translation of foreign operations
B15: Exchange differences on translation of discontinued operation
B16: Changes in the fair value of cash flow hedges
B17: Net investment hedge
B18: Income tax relating to these items
L19: =SUM(L13:L18) -> 0 | N19: =SUM(N13:N18) -> 0
B20: Items that will not be subsequently reclassified to profit or loss
B21: Gain on revaluation of land and buildings
B22: Remeasurements of retirement benefit obligations
B23: Income tax relating to these items
L24: =SUM(L21:L23) -> 0 | N24: =SUM(N21:N23) -> 0
B26: =IF(AND(L26>=0,N26>=0),"Other comprehensive income",IF(AND(L26>=0,N26<0),"Other comprehensive income / (loss)",IF(AND(L26<0,N26>=0),"Other comprehensive (loss) / income","Other comprehensive loss"))) -> Other comprehensive income | L26: =L19+L24 -> 0 | N26: =N19+N24 -> 0
B28: =IF(AND(L28>=0,N28>=0),"Total comprehensive income for the year",IF(AND(L28>=0,N28<0),"Total comprehensive income / (loss) for the year",IF(AND(L28<0,N28>=0),"Total comprehensive (loss) / income for the year","Total comprehensive loss for the year"))) -> Total comprehensive income for the year | L28: =L8+L26 -> 0 | N28: =N8+N26 -> 0
B30: =SOFP!B63 -> The annexed notes from 1 to 38 form an integral part of these financial statements.
B36: =SOFP!B69 -> Chief Executive | L36: =SOFP!L69 -> Director

Sheet SOCF
B1: =Cover!C1 -> ABC LIMITED
B2: STATEMENT OF CASH FLOWS
B3: =Cover!C3 -> FOR THE YEAR ENDED JUNE 30, 2023
J5: =SOFP!J5 -> Note | L5: =SOFP!L5 -> 2023 | N5: =SOFP!N5 -> 2022
L6: =SOFP!L6 -> ------------- Rupees -------------
B8: Cash flows from operating activities
B9: =SOPL!B28 -> Profit before tax | L9: =SOPL!L28 -> 0 | N9: =SOPL!N28 -> 0
B10: Adjustments for:
L20: =SUM(L11:L19) -> 0 | N20: =SUM(N11:N19) -> 0
B21: =IF(AND(L21>=0,N21>=0),"Operating profit before working capital changes",IF(AND(L21>=0,N21<0),"Operating profit / (loss) before working capital changes",IF(AND(L21<0,N21>=0),"Operating (loss) / profit before working capital changes","Operating loss before working capital changes"))) -> Operating profit before working capital changes | L21: =L9+L20 -> 0 | N21: =N9+N20 -> 0
B23: Effect of working capital changes
B24: (Increase) / decrease in current assets
L29: =SUM(L25:L28) -> 0 | N29: =SUM(N25:N28) -> 0
B30: Increase / (decrease) in current liabilities
L35: =SUM(L31:L34) -> 0 | N35: =SUM(N31:N34) -> 0
B37: =IF(AND(L37>=0,N37>=0),"Cash generated from operations",IF(AND(L37>=0,N37<0),"Cash generated from / (used in) operations",IF(AND(L37<0,N37>=0),"Cash (used in) / generated from operations","Cash used in operations"))) -> Cash generated from operations | L37: =L21+L29+L35 -> 0 | N37: =N21+N29+N35 -> 0
B39: Interest received
B40: Interest paid
B41: Income taxes paid
B42: Lease payments (interest portion)
B43: Short-term lease payments (low values assets and variable lease payments not included in lease liability)
L46: =SUM(L39:L45) -> 0 | N46: =SUM(N39:N45) -> 0
B48: =IF(AND(L48>0,N48>0),"Net cash inflows from operating activities",IF(AND(L48>=0,N48<0),"Net cash inflows / (outflows) from operating activities",IF(AND(L48<0,N48>=0),"Net cash (outflows) / inflows from operating activities",IF(AND(L48=0,N48=0),"Net cash flows from operating activities","Net cash outflows from operating activities")))) -> Net cash flows from operating activities | L48: =L37+L46 -> 0 | N48: =N37+N46 -> 0
B50: Cash flows from investing activities
B51: Payments for property, plant and equipment
B52: Payments for investment property
B53: Payments for available-for-sale financial assets
B54: Payments for held-to-maturity investments
B55: Payments for patents and trademarks
B56: Payment of software development costs
B57: Loans to related parties
B58: Proceeds from sale of property, plant and equipment
B59: Proceeds from sale of available-for-sale financial assets
B60: Repayment of loans by related parties
B61: Dividends received
B62: Interest received on available-for-sale financial assets
B64: =IF(AND(L64>0,N64>0),"Net cash inflows from investing activities",IF(AND(L64>=0,N64<0),"Net cash inflows / (outflows) from investing activities",IF(AND(L64<0,N64>=0),"Net cash (outflows) / inflows from investing activities",IF(AND(L64=0,N64=0),"Net cash flows from investing activities","Net cash outflows from investing activities")))) -> Net cash flows from investing activities | L64: =SUM(L51:L63) -> 0 | N64: =SUM(N51:N63) -> 0
B66: Cash flows from financing activities
B67: Proceeds from issues of shares and other equity securities
B68: Proceeds from borrowings
...

Sheet SOCIE
B1: =Cover!C1 -> ABC LIMITED
B2: STATEMENT OF CHANGES IN EQUITY
B3: =Cover!C3 -> FOR THE YEAR ENDED JUNE 30, 2023
F5: =SOFP!J5 -> Note | H5: =SOFP!B35 -> Issued, subscribed and paid up share capital | J5: =SOFP!B36 -> Share deposit money | L5: =SOFP!B37 -> Other reserves | N5: =SOFP!B38 -> Retained earnings | P5: Total share capital and reserves
H6: ="------------------------"&SOFP!L6&"------------------------" -> ------------------------------------- Rupees -------------------------------------
B8: =("Balance as at " &Cover!E7) -> Balance as at July 01, 2021 | P8: =SUM(H8:N8) -> 0
B10: =IF(P10>=0,"Profit for the year","Loss for the year") -> Profit for the year | P10: =SUM(H10:N10) -> 0
B12: =IF(P12>=0,"Other comprehensive income for the year","Other comprehensive loss for the year") -> Other comprehensive income for the year | N12: =SOCI!N26 -> 0 | P12: =SUM(H12:N12) -> 0
B14: =("Balance as at " &Cover!G7) -> Balance as at June 30, 2022 | H14: =SUM(H8:H13) -> 0 | J14: =SUM(J8:J13) -> 0 | L14: =SUM(L8:L13) -> 0 | N14: =SUM(N8:N13) -> 0 | P14: =SUM(P8:P13) -> 0
B16: =("Balance as at " &Cover!E6) -> Balance as at July 01, 2022 | H16: =H14 -> 0 | J16: =J14 -> 0 | L16: =L14 -> 0 | N16: =N14 -> 0 | P16: =SUM(H16:N16) -> 0
B18: =IF(P18>=0,"Profit for the year","Loss for the year") -> Profit for the year | N18: =SOPL!L32 -> 0 | P18: =SUM(H18:N18) -> 0
B20: =IF(P20>=0,"Other comprehensive income for the year","Other comprehensive loss for the year") -> Other comprehensive income for the year | N20: =SOCI!L26 -> 0 | P20: =SUM(H20:N20) -> 0
B22: =("Balance as at " &Cover!G6) -> Balance as at June 30, 2023 | H22: =SUM(H16:H21) -> 0 | J22: =SUM(J16:J21) -> 0 | L22: =SUM(L16:L21) -> 0 | N22: =SUM(N16:N21) -> 0 | P22: =SUM(P16:P21) -> 0
B24: =SOFP!B63 -> The annexed notes from 1 to 38 form an integral part of these financial statements.
B30: =SOFP!B69 -> Chief Executive | N30: =SOFP!L69 -> Director

Sheet Policies
A1: =Cover!C1 -> ABC LIMITED
A2: NOTES TO THE FINANCIAL STATEMENTS
A3: =Cover!C3 -> FOR THE YEAR ENDED JUNE 30, 2023
A5: 1 | B5: Status and nature of business
B7: ABC Limited (the Company) was incorporated in Pakistan on _________________ as a Private Limited Company under the repealed Companies Ordinance, 1984. The company is principally engaged in ___________________. The registered office of the company is located at ________________________. (If the Company is a Manufacturer and its registered office is located at a location other than Manufacturing Facility then, The manufacturing facility of the company is located at ___________________________).
A13: =A5+1 -> 2 | B13: Basis of preparation
A15: =A13+0.1 -> 2.1 | B15: Basis of measurement
B17: =IF(Cover!E13="Cost","These financial statements have been prepared under the historical cost convention unless otherwise specifically stated, if any,","These financial statements have been prepared under the historical cost convention unless otherwise specifically stated, except for, "&"certain items of property, plant and equipment, which are stated at revalued amount less accumulated depreciation and impairment losses, if any.") -> These financial statements have been prepared under the historical cost convention unless otherwise specifically stated, if any,
A20: =A15+0.1 -> 2.2 | B20: Statement of compliance
B22: These financial statements have been prepared in accordance with the approved accounting standards as applicable in Pakistan and the requirements of Companies Act, 2017. Approved accounting standards comprise of:
A24: - | B24: =VLOOKUP(Cover!$E$12,Cover!$I$14:$J$17,2,FALSE) -> Revised Accounting and Financial Reporting Standards for Small Sized Entities (Revised AFRS for SSEs) issued by the Institute of Chartered Accountants of Pakistan (ICAP) as notified under the Companies Act, 2017; and
A26: - | B26: Islamic Financial Accounting Standards (IFASs) as issued by the Institute of Chartered Accountants of Pakistan (ICAP); and
A27: - | B27: Provisions of and directives issued under the Companies Act, 2017.
B28: Wherever, the requirements of the Companies Act, 2017 or directives issued by the Securities and Exchange Commission of Pakistan differs with the requirements of these accounting standards, the requirements of the Companies Act, 2017 or the requirements of the said directives shall prevail.
A32: =A20+0.1 -> 2.3 | B32: Functional and presentational currency
B34: These financial statements have been prepared in Pakistani Rupees (PKR), which is the company's functional and presentational currency
A36: =A13+1 -> 3 | B36: Use of judgments, estimates and assumptions
B38: The preparation of financial statements in conformity with the accounting and reporting standards requires the use of certain critical accounting estimates. It also requires management to exercise its judgement in the process of applying the Company’s accounting policies. Estimates and judgements are continually evaluated and are based on historic experience and other factors, including expectation of future events that are believed to be reasonable under the circumstances. In the process of applying the Company’s accounting policies, the management has made the following estimates and judgements which are significant to the financial statements:
A45: - | B45: ="assumptions and estimates used in determining the recoverable amount, residual values and useful lives of "&LOWER(SOFP!B10)&"(Note "&TEXT(SOFP!J10,"##")&");" -> assumptions and estimates used in determining the recoverable amount, residual values and useful lives of property, plant and equipment (Note 5);
A49: - | B49: ="assumptions and estimates used in deriving fair value of "&LOWER(SOFP!B11)&"(Note "&TEXT(SOFP!J11,"##")&");" -> assumptions and estimates used in deriving fair value of investment properties (Note 6);
A51: - | B51: ="assumptions and estimates used in determining the recoverable amount, residual values and useful lives of "&LOWER(SOFP!B12)&"(Note "&TEXT(SOFP!J12,"##")&");" -> assumptions and estimates used in determining the recoverable amount, residual values and useful lives of intangible assets (Note 7);
A54: - | B54: =LOWER(SOFP!B14)&" is recognised only to the extent that it is probable that future taxable profits will be available against which the assets may be utilised"&" (Note "&TEXT(SOFP!J14,"##")&");" -> deferred tax assets is recognised only to the extent that it is probable that future taxable profits will be available against which the assets may be utilised (Note 9);
A57: - | B57: ="assumptions and estimates used in determining the provision for slow moving and obsolete "&LOWER(SOFP!B19)&"(Note "&TEXT(SOFP!J19,"##")&");" -> assumptions and estimates used in determining the provision for slow moving and obsolete stores, spares and loose tools (Note 10);
A60: - | B60: ="assumptions and estimates used in writing down items of "&LOWER(SOFP!B20)&" to their net realisable value "&"(Note "&TEXT(SOFP!J20,"##")&");" -> assumptions and estimates used in writing down items of inventories to their net realisable value (Note 11);
A62: - | B62: ="assumptions and estimates used in calculating the provision for impairment for "&LOWER(SOFP!B21)&"(Note "&TEXT(SOFP!J21,"##")&");" -> assumptions and estimates used in calculating the provision for impairment for trade receivables - net (Note 12);
A64: - | B64: ="assumptions and estimates used in calculating the provision for impairment for "&LOWER(SOFP!B22)&"(Note "&TEXT(SOFP!J22,"##")&");" -> assumptions and estimates used in calculating the provision for impairment for advances, deposits and prepayments (Note 13);
A68: - | B68: ="assumptions and estimates used in disclosure and assessment of provision for "&LOWER(SOFP!B57)&"(Note "&TEXT(SOFP!J57,"##")&");" -> assumptions and estimates used in disclosure and assessment of provision for contingencies and commitments (Note 22);
A70: - | B70: ="assumptions and estimates used in determining current income under relevant tax law and the decisions of appellate authorities on certain cases issued in the past "&"(Note "&TEXT(SOPL!J30,"##")&");" -> assumptions and estimates used in determining current income under relevant tax law and the decisions of appellate authorities on certain cases issued in the past (Note 31);
A73: =A36+1 -> 4 | B73: Summary of significant accounting policies
A75: =A73+0.1 -> 4.1 | B75: =SOFP!B10 -> Property, plant and equipment
B77: =B75&" are stated at cost less accumulated depreciation and impairment losses, if any, Cost includes expenditures directly attributable to the acquisition of an asset." -> Property, plant and equipment are stated at cost less accumulated depreciation and impairment losses, if any, Cost includes expenditures directly attributable to the acquisition of an asset.
B80: Capital work-in-progress is stated at cost accumulated to the date of statement of financial position less impairment losses, if any.
B82: ="Depreciation on "&LOWER(B75)&" is charged on reducing balance method at the rates stated in Note "&FAS!A5&" to these financial statements. Depreciation charge commences from the month in which asset is available for use and continues until the month of disposal." -> Depreciation on property, plant and equipment is charged on reducing balance method at the rates stated in Note 5 to these financial statements. Depreciation charge commences from the month in which asset is available for use and continues until the month of disposal.
B86: Residual values and the useful lives are reviewed at each date of statement of financial position and adjusted if expectations differ significantly from previous estimates.
B89: ="Residual values are determined by the management as the amount it expects it would receive currently for an item of "&LOWER(B75)&" if it was already of the age and in the condition expected at the end of its useful life based on the prevailing market prices of similar assets already at the end of their useful lives." -> Residual values are determined by the management as the amount it expects it would receive currently for an item of property, plant and equipment if it was already of the age and in the condition expected at the end of its useful life based on the prevailing market prices of similar assets already at the end of their useful lives.
B93: Useful lives are determined by the management based on the expected usage of assets, physical wear and tear, technical and commercial obsolescence, legal and similar limits on the use of the assets and other similar factors.
B96: ="The carrying values of "&LOWER(B75)&" are reviewed at each reporting date for indications that an asset may be impaired and carrying values may not be recovered."&" If any such indication exists and where the carrying value exceeds the estimated recoverable amount, the asset or cash generating unit is written down to its recoverable amount. The recoverable amount of "&LOWER(B75)&" is the greater of fair value less cost to sell and value in use." -> The carrying values of property, plant and equipment are reviewed at each reporting date for indications that an asset may be impaired and carrying values may not be recovered. If any such indication exists and where the carrying value exceeds the estimated recoverable amount, the asset or cash generating unit is written down to its recoverable amount. The recoverable amount of property, plant and equipment is the greater of fair value less cost to sell and value in use.
B101: Normal repairs and maintenance are charged to profit or loss as and when incurred. Major renewals and improvements, if any, are capitalised, when it is probable that future economic benefits will flow to the Company.
B104: ="An item of "&LOWER(B75)&" is derecognised upon disposal or when no future economic benefits are expected from its use or disposal. Gains and losses on disposals are determined by comparing proceeds with carrying amount of the relevant assets. These are included in profit or loss." -> An item of property, plant and equipment is derecognised upon disposal or when no future economic benefits are expected from its use or disposal. Gains and losses on disposals are determined by comparing proceeds with carrying amount of the relevant assets. These are included in profit or loss.
A108: =A75+0.1 -> 4.2 | B108: Investment properties
...

Sheet FAS
A1: =Cover!C1 -> ABC LIMITED
A2: =Policies!A2 -> NOTES TO THE FINANCIAL STATEMENTS
A3: =Cover!C3 -> FOR THE YEAR ENDED JUNE 30, 2023
A5: =SOFP!J10 -> 5 | B5: =SOFP!B10 -> Property, plant and equipment | J5: =SOFP!J5 -> Note | L5: =SOFP!L5 -> 2023 | N5: =SOFP!N5 -> 2022
L6: =SOFP!L6 -> ------------- Rupees -------------
B8: Operating fixed assets | J8: =A13 -> 5.1 | L8: =Z66 -> 0 | N8: =Z64 -> 0
B9: Capital work in progress
L11: =SUM(L8:L10) -> 0 | N11: =SUM(N8:N10) -> 0
A13: =A5+0.1 -> 5.1 | B13: =B8 -> Operating fixed assets
H14: Owned assets | Z14: Total assets
H15: Freehold Land | J15: Building on Freehold Land | L15: Plant and Machinery | N15: Generator | P15: Office Equipment | R15: Computers | T15: Electric Equipment & Installations | V15: Furniture and Fixture | X15: Vehicles
H16: =SOCIE!H6 -> ------------------------------------- Rupees -------------------------------------
A18: Cost/Revaluation
B20: =("Balance as at " &Cover!E7 &" - Cost") -> Balance as at July 01, 2021 - Cost | L20: 0 | R20: 0 | V20: 0 | Z20: =SUM(H20:X20) -> 0
B21: =("Balance as at " &Cover!E7 &" - Revaluation") -> Balance as at July 01, 2021 - Revaluation | H21: 0 | Z21: =SUM(H21:X21) -> 0
H22: =SUM(H20:H21) -> 0 | J22: =SUM(J20:J21) -> 0 | L22: =SUM(L20:L21) -> 0 | N22: =SUM(N20:N21) -> 0 | P22: =SUM(P20:P21) -> 0 | R22: =SUM(R20:R21) -> 0 | T22: =SUM(T20:T21) -> 0 | V22: =SUM(V20:V21) -> 0 | X22: =SUM(X20:X21) -> 0 | Z22: =SUM(H22:X22) -> 0
B24: Additions during the year | Z24: =SUM(H24:X24) -> 0
B26: Disposals | Z26: =SUM(H26:X26) -> 0
B28: =("Balance as at " &Cover!G7) -> Balance as at June 30, 2022 | H28: =SUM(H22:H27) -> 0 | J28: =SUM(J22:J27) -> 0 | L28: =SUM(L22:L27) -> 0 | N28: =SUM(N22:N27) -> 0 | P28: =SUM(P22:P27) -> 0 | R28: =SUM(R22:R27) -> 0 | T28: =SUM(T22:T27) -> 0 | V28: =SUM(V22:V27) -> 0 | X28: =SUM(X22:X27) -> 0 | Z28: =SUM(H28:X28) -> 0
B30: =("Balance as at " &Cover!E6 &" - Cost") -> Balance as at July 01, 2022 - Cost | H30: =H28-H31 -> 0 | J30: =J28-J31 -> 0 | L30: =L28-L31 -> 0 | N30: =N28-N31 -> 0 | P30: =P28-P31 -> 0 | R30: =R28-R31 -> 0 | T30: =T28-T31 -> 0 | V30: =V28-V31 -> 0 | X30: =X28-X31 -> 0 | Z30: =SUM(H30:X30) -> 0
B31: =("Balance as at " &Cover!E6 &" - Revaluation") -> Balance as at July 01, 2022 - Revaluation | Z31: =SUM(H31:X31) -> 0
H32: =SUM(H30:H31) -> 0 | J32: =SUM(J30:J31) -> 0 | L32: =SUM(L30:L31) -> 0 | N32: =SUM(N30:N31) -> 0 | P32: =SUM(P30:P31) -> 0 | R32: =SUM(R30:R31) -> 0 | T32: =SUM(T30:T31) -> 0 | V32: =SUM(V30:V31) -> 0 | X32: =SUM(X30:X31) -> 0 | Z32: =SUM(H32:X32) -> 0
B34: Additions during the year | Z34: =SUM(H34:X34) -> 0
B36: Disposals | L36: =-L32*0.1 -> 0 | Z36: =SUM(H36:X36) -> 0
B38: =("Balance as at " &Cover!G6) -> Balance as at June 30, 2023 | H38: =SUM(H32:H37) -> 0 | J38: =SUM(J32:J37) -> 0 | L38: =SUM(L32:L37) -> 0 | N38: =SUM(N32:N37) -> 0 | P38: =SUM(P32:P37) -> 0 | R38: =SUM(R32:R37) -> 0 | T38: =SUM(T32:T37) -> 0 | V38: =SUM(V32:V37) -> 0 | X38: =SUM(X32:X37) -> 0 | Z38: =SUM(H38:X38) -> 0
A40: Depreciation
B42: =B20 -> Balance as at July 01, 2021 - Cost | Z42: =SUM(H42:X42) -> 0
B43: =B21 -> Balance as at July 01, 2021 - Revaluation | Z43: =SUM(H43:X43) -> 0
H44: =SUM(H42:H43) -> 0 | J44: =SUM(J42:J43) -> 0 | L44: =SUM(L42:L43) -> 0 | N44: =SUM(N42:N43) -> 0 | P44: =SUM(P42:P43) -> 0 | R44: =SUM(R42:R43) -> 0 | T44: =SUM(T42:T43) -> 0 | V44: =SUM(V42:V43) -> 0 | X44: =SUM(X42:X43) -> 0 | Z44: =SUM(H44:X44) -> 0
B46: Charge for the year | Z46: =SUM(H46:X46) -> 0
B48: Depreciation on disposals | Z48: =SUM(H48:X48) -> 0
B50: =B28 -> Balance as at June 30, 2022 | H50: =SUM(H44:H49) -> 0 | J50: =SUM(J44:J49) -> 0 | L50: =SUM(L44:L49) -> 0 | N50: =SUM(N44:N49) -> 0 | P50: =SUM(P44:P49) -> 0 | R50: =SUM(R44:R49) -> 0 | T50: =SUM(T44:T49) -> 0 | V50: =SUM(V44:V49) -> 0 | X50: =SUM(X44:X49) -> 0 | Z50: =SUM(H50:X50) -> 0
B52: =B30 -> Balance as at July 01, 2022 - Cost | H52: =H50 -> 0 | J52: =J50 -> 0 | L52: =L50 -> 0 | N52: =N50 -> 0 | P52: =P50 -> 0 | R52: =R50 -> 0 | T52: =T50 -> 0 | V52: =V50 -> 0 | X52: =X50 -> 0 | Z52: =SUM(H52:X52) -> 0
B53: =B31 -> Balance as at July 01, 2022 - Revaluation | Z53: =SUM(H53:X53) -> 0
H54: =SUM(H52:H53) -> 0 | J54: =SUM(J52:J53) -> 0 | L54: =SUM(L52:L53) -> 0 | N54: =SUM(N52:N53) -> 0 | P54: =SUM(P52:P53) -> 0 | R54: =SUM(R52:R53) -> 0 | T54: =SUM(T52:T53) -> 0 | V54: =SUM(V52:V53) -> 0 | X54: =SUM(X52:X53) -> 0 | Z54: =SUM(H54:X54) -> 0
B56: Charge for the year | H56: =-AD!K14 -> 0 | J56: =-AD!K19 -> 0 | L56: =-AD!K24 -> 0 | N56: =-AD!K29 -> 0 | P56: =-AD!K34 -> 0 | R56: =-AD!K39 -> 0 | T56: =-AD!K44 -> 0 | V56: =-AD!K49 -> 0 | X56: =-AD!K54 -> 0 | Z56: =SUM(H56:X56) -> 0
B58: Depreciation on disposals | H58: =-AD!N69 -> 0 | J58: =-AD!N73 -> 0 | L58: =-AD!N77 -> 0 | N58: =-AD!N81 -> 0 | P58: =-AD!N85 -> 0 | R58: =-AD!N89 -> 0 | T58: =-AD!N93 -> 0 | V58: =-AD!N97 -> 0 | X58: =-AD!N101 -> 0 | Z58: =SUM(H58:X58) -> 0
B60: =B38 -> Balance as at June 30, 2023 | H60: =SUM(H54:H59) -> 0 | J60: =SUM(J54:J59) -> 0 | L60: =SUM(L54:L59) -> 0 | N60: =SUM(N54:N59) -> 0 | P60: =SUM(P54:P59) -> 0 | R60: =SUM(R54:R59) -> 0 | T60: =SUM(T54:T59) -> 0 | V60: =SUM(V54:V59) -> 0 | X60: =SUM(X54:X59) -> 0 | Z60: =SUM(H60:X60) -> 0
A62: Rate of depreciation
A64: =("Written down value as at " &Cover!G7) -> Written down value as at June 30, 2022 | H64: =H28-H50 -> 0 | J64: =J28-J50 -> 0 | L64: =L28-L50 -> 0 | N64: =N28-N50 -> 0 | P64: =P28-P50 -> 0 | R64: =R28-R50 -> 0 | T64: =T28-T50 -> 0 | V64: =V28-V50 -> 0 | X64: =X28-X50 -> 0 | Z64: =SUM(H64:X64) -> 0
...

Sheet Notes
A1: =Cover!C1 -> ABC LIMITED
A2: =Policies!A2 -> NOTES TO THE FINANCIAL STATEMENTS
A3: =Cover!C3 -> FOR THE YEAR ENDED JUNE 30, 2023
A5: =FAS!A68+0.1 -> 5.3 | B5: Following are the property/assets acquired with the fund of the company, is not held in the name of the company or is not in the possession and control of the company.
Q7: Impairment losses recognised during the year
B8: Particulars of property/assets | F8: Classified as | H8: Particulars of person | L8: =SOFP!$J$5 -> Note | N8: Value of the property/assets | Q8: IAS 36:130(a)-(g)
Q9: IAS 36:131
N10: Rupees | Q10: IAS 36:126(a)
Q11: The discount rate used in measuring value in use was __ per cent per annum. No impairment assessment was
F12: =FAS!H15 -> Freehold Land | L12: =A22 -> 5.3.1 | Q12: performed in 2019 as there was no indication of impairment.
F13: =FAS!J15 -> Building on Freehold Land | Q13: These losses are attributable to greater than anticipated wear and tear. Those assets have been impaired in full and
F14: =FAS!L15 -> Plant and Machinery | Q14: The impairment losses have been included in the profit and loss in the [other expenses/cost of sales] line item.
F15: =FAS!N15 -> Generator | Q15: IAS 16:74(a) Assets pledged as security
F16: =FAS!P15 -> Office Equipment | Q16: Freehold land and buildings with a carrying amount of CU__ million (2019: CU__ million) have been pledged to
F17: =FAS!R15 -> Computers | Q17: secure borrowings of the Group (see note 33). The Group is not allowed to pledge these assets as security for other
F18: =FAS!T15 -> Electric Equipment & Installations | Q18: borrowings or to sell them to another entity.
F19: =FAS!V15 -> Furniture and Fixture
F20: =FAS!X15 -> Vehicles
A22: =A5&".1" -> 5.3.1 | B22: Reason for the property or assets not being in the name of or possession of control of the company
J27: Note | L27: =SOFP!$L$5 -> 2023 | N27: =SOFP!$N$5 -> 2022
L28: =SOFP!$L$6 -> ------------- Rupees -------------
A30: =A5+0.1 -> 5.4 | B30: Depreciation for the year has been allocated as under:
B31: =SOPL!B10 -> Cost of revenue
B32: =SOPL!B14 -> Distribution costs
B33: =SOPL!B15 -> Administrative expenses
L35: =SUM(L31:L34) -> 0 | N35: =SUM(N31:N34) -> 0
A37: =A30+0.1 -> 5.5 | B37: Freehold Land, building, furniture and fixture and plant and machinery were revalued by M/s _________________ as on ___________.
A40: =A37+0.1 -> 5.6 | B40: Forced Sales Value (FSV) of the land, building, furniture and fixture and plant and machinery was Rs. _____ million , _____ million, Rs. ______ thousand and ___________ million respectively as at date of valuation.
A43: =A40+0.1 -> 5.7 | B43: ="Had there been no revaluation, the cost, accumulated depreciation and book value of revalued assets as at "&Cover!G6&" would have been as under:" -> Had there been no revaluation, the cost, accumulated depreciation and book value of revalued assets as at June 30, 2023 would have been as under:
J46: Cost | L46: Accumulated Depreciation | N46: Book Value
J47: =SOFP!$L$6 -> ------------- Rupees -------------
B49: =FAS!H15 -> Freehold Land | J49: =FAS!H30+FAS!H34-FAS!H36 -> 0 | L49: =FAS!H52+FAS!H56 -> 0 | N49: =J49-L49 -> 0
B50: =FAS!J15 -> Building on Freehold Land | J50: =FAS!J30+FAS!J34-FAS!J36 -> 0 | L50: =FAS!J52+FAS!J56-#REF! -> #REF! | N50: =J50-L50 -> #REF!
B51: =FAS!V15 -> Furniture and Fixture | J51: =FAS!V30+FAS!V34-FAS!V36 -> 0 | L51: =FAS!V52+FAS!V56-#REF! -> #REF! | N51: =J51-L51 -> #REF!
B52: =FAS!L15 -> Plant and Machinery | J52: =FAS!L30+FAS!L34-FAS!L36 -> 0 | L52: =FAS!L52+FAS!L56-#REF! -> #REF! | N52: =J52-L52 -> #REF!
B54: =FAS!B60 -> Balance as at June 30, 2023 | J54: =SUM(J49:J53) -> 0 | L54: =SUM(L49:L53) -> #REF! | N54: =SUM(N49:N53) -> #REF!
B56: =FAS!B50 -> Balance as at June 30, 2022 | J56: =FAS!H30+FAS!J30+FAS!V30+FAS!L30 -> 0 | L56: =FAS!H52+FAS!J52+FAS!V52+FAS!L52 -> 0 | N56: =J56-L56 -> 0
J60: Note | L60: =SOFP!$L$5 -> 2023 | N60: =SOFP!$N$5 -> 2022
L61: =SOFP!$L$6 -> ------------- Rupees -------------
A63: =SOFP!J11 -> 6 | B63: =SOFP!B11 -> Investment properties
...

Sheet CS
B1: =Cover!C1 -> ABC LIMITED
B2: CONTROL SHEET
B3: =Cover!C3 -> FOR THE YEAR ENDED JUNE 30, 2023
E5: =D6-E6 -> 0 | G5: =F6-G6 -> 0 | I5: =H6-I6 -> 0
D6: =D306 -> 0 | E6: =E306 -> 0 | F6: =F306 -> 0 | G6: =G306 -> 0 | H6: =H306 -> 0 | I6: =I306 -> 0
B8: Financial Statements Heads / SubHeads | D8: Opening Balances | F8: Accumulated Activity | H8: Closing Balances
D9: Debit | E9: Credit | F9: Debit | G9: Credit | H9: Debit | I9: Credit
B10: .
B11: ASSETS | D11: =SUMIF(ATB!D:D,CS!B:B,ATB!F:F) -> 0 | E11: =SUMIF(ATB!D:D,CS!B:B,ATB!G:G) -> 0 | F11: =SUMIF(ATB!D:D,CS!B:B,ATB!H:H)+SUMIF(ATB!D:D,CS!B:B,ATB!J:J) -> 0 | G11: =SUMIF(ATB!D:D,CS!B:B,ATB!I:I)+SUMIF(ATB!D:D,CS!B:B,ATB!K:K) -> 0 | H11: =SUMIF(ATB!D:D,CS!B:B,ATB!L:L) -> 0 | I11: =SUMIF(ATB!D:D,CS!B:B,ATB!M:M) -> 0
B12: Non-current assets | D12: =SUMIF(ATB!D:D,CS!B:B,ATB!F:F) -> 0 | E12: =SUMIF(ATB!D:D,CS!B:B,ATB!G:G) -> 0 | F12: =SUMIF(ATB!D:D,CS!B:B,ATB!H:H)+SUMIF(ATB!D:D,CS!B:B,ATB!J:J) -> 0 | G12: =SUMIF(ATB!D:D,CS!B:B,ATB!I:I)+SUMIF(ATB!D:D,CS!B:B,ATB!K:K) -> 0 | H12: =SUMIF(ATB!D:D,CS!B:B,ATB!L:L) -> 0 | I12: =SUMIF(ATB!D:D,CS!B:B,ATB!M:M) -> 0
B13: Property, plant and equipment | D13: =SUMIF(ATB!D:D,CS!B:B,ATB!F:F) -> 0 | E13: =SUMIF(ATB!D:D,CS!B:B,ATB!G:G) -> 0 | F13: =SUMIF(ATB!D:D,CS!B:B,ATB!H:H)+SUMIF(ATB!D:D,CS!B:B,ATB!J:J) -> 0 | G13: =SUMIF(ATB!D:D,CS!B:B,ATB!I:I)+SUMIF(ATB!D:D,CS!B:B,ATB!K:K) -> 0 | H13: =SUMIF(ATB!D:D,CS!B:B,ATB!L:L) -> 0 | I13: =SUMIF(ATB!D:D,CS!B:B,ATB!M:M) -> 0
B14: Freehold Land | D14: =SUMIF(ATB!D:D,CS!B:B,ATB!F:F) -> 0 | E14: =SUMIF(ATB!D:D,CS!B:B,ATB!G:G) -> 0 | F14: =SUMIF(ATB!D:D,CS!B:B,ATB!H:H)+SUMIF(ATB!D:D,CS!B:B,ATB!J:J) -> 0 | G14: =SUMIF(ATB!D:D,CS!B:B,ATB!I:I)+SUMIF(ATB!D:D,CS!B:B,ATB!K:K) -> 0 | H14: =SUMIF(ATB!D:D,CS!B:B,ATB!L:L) -> 0 | I14: =SUMIF(ATB!D:D,CS!B:B,ATB!M:M) -> 0
B15: Building on Freehold Land | D15: =SUMIF(ATB!D:D,CS!B:B,ATB!F:F) -> 0 | E15: =SUMIF(ATB!D:D,CS!B:B,ATB!G:G) -> 0 | F15: =SUMIF(ATB!D:D,CS!B:B,ATB!H:H)+SUMIF(ATB!D:D,CS!B:B,ATB!J:J) -> 0 | G15: =SUMIF(ATB!D:D,CS!B:B,ATB!I:I)+SUMIF(ATB!D:D,CS!B:B,ATB!K:K) -> 0 | H15: =SUMIF(ATB!D:D,CS!B:B,ATB!L:L) -> 0 | I15: =SUMIF(ATB!D:D,CS!B:B,ATB!M:M) -> 0
B16: Plant and Machinery | D16: =SUMIF(ATB!D:D,CS!B:B,ATB!F:F) -> 0 | E16: =SUMIF(ATB!D:D,CS!B:B,ATB!G:G) -> 0 | F16: =SUMIF(ATB!D:D,CS!B:B,ATB!H:H)+SUMIF(ATB!D:D,CS!B:B,ATB!J:J) -> 0 | G16: =SUMIF(ATB!D:D,CS!B:B,ATB!I:I)+SUMIF(ATB!D:D,CS!B:B,ATB!K:K) -> 0 | H16: =SUMIF(ATB!D:D,CS!B:B,ATB!L:L) -> 0 | I16: =SUMIF(ATB!D:D,CS!B:B,ATB!M:M) -> 0
B17: Generator | D17: =SUMIF(ATB!D:D,CS!B:B,ATB!F:F) -> 0 | E17: =SUMIF(ATB!D:D,CS!B:B,ATB!G:G) -> 0 | F17: =SUMIF(ATB!D:D,CS!B:B,ATB!H:H)+SUMIF(ATB!D:D,CS!B:B,ATB!J:J) -> 0 | G17: =SUMIF(ATB!D:D,CS!B:B,ATB!I:I)+SUMIF(ATB!D:D,CS!B:B,ATB!K:K) -> 0 | H17: =SUMIF(ATB!D:D,CS!B:B,ATB!L:L) -> 0 | I17: =SUMIF(ATB!D:D,CS!B:B,ATB!M:M) -> 0
B18: Office Equipment | D18: =SUMIF(ATB!D:D,CS!B:B,ATB!F:F) -> 0 | E18: =SUMIF(ATB!D:D,CS!B:B,ATB!G:G) -> 0 | F18: =SUMIF(ATB!D:D,CS!B:B,ATB!H:H)+SUMIF(ATB!D:D,CS!B:B,ATB!J:J) -> 0 | G18: =SUMIF(ATB!D:D,CS!B:B,ATB!I:I)+SUMIF(ATB!D:D,CS!B:B,ATB!K:K) -> 0 | H18: =SUMIF(ATB!D:D,CS!B:B,ATB!L:L) -> 0 | I18: =SUMIF(ATB!D:D,CS!B:B,ATB!M:M) -> 0
B19: Computers | D19: =SUMIF(ATB!D:D,CS!B:B,ATB!F:F) -> 0 | E19: =SUMIF(ATB!D:D,CS!B:B,ATB!G:G) -> 0 | F19: =SUMIF(ATB!D:D,CS!B:B,ATB!H:H)+SUMIF(ATB!D:D,CS!B:B,ATB!J:J) -> 0 | G19: =SUMIF(ATB!D:D,CS!B:B,ATB!I:I)+SUMIF(ATB!D:D,CS!B:B,ATB!K:K) -> 0 | H19: =SUMIF(ATB!D:D,CS!B:B,ATB!L:L) -> 0 | I19: =SUMIF(ATB!D:D,CS!B:B,ATB!M:M) -> 0
B20: Electric Equipment & Installations | D20: =SUMIF(ATB!D:D,CS!B:B,ATB!F:F) -> 0 | E20: =SUMIF(ATB!D:D,CS!B:B,ATB!G:G) -> 0 | F20: =SUMIF(ATB!D:D,CS!B:B,ATB!H:H)+SUMIF(ATB!D:D,CS!B:B,ATB!J:J) -> 0 | G20: =SUMIF(ATB!D:D,CS!B:B,ATB!I:I)+SUMIF(ATB!D:D,CS!B:B,ATB!K:K) -> 0 | H20: =SUMIF(ATB!D:D,CS!B:B,ATB!L:L) -> 0 | I20: =SUMIF(ATB!D:D,CS!B:B,ATB!M:M) -> 0
B21: Furniture and Fixture | D21: =SUMIF(ATB!D:D,CS!B:B,ATB!F:F) -> 0 | E21: =SUMIF(ATB!D:D,CS!B:B,ATB!G:G) -> 0 | F21: =SUMIF(ATB!D:D,CS!B:B,ATB!H:H)+SUMIF(ATB!D:D,CS!B:B,ATB!J:J) -> 0 | G21: =SUMIF(ATB!D:D,CS!B:B,ATB!I:I)+SUMIF(ATB!D:D,CS!B:B,ATB!K:K) -> 0 | H21: =SUMIF(ATB!D:D,CS!B:B,ATB!L:L) -> 0 | I21: =SUMIF(ATB!D:D,CS!B:B,ATB!M:M) -> 0
B22: Vehicles | D22: =SUMIF(ATB!D:D,CS!B:B,ATB!F:F) -> 0 | E22: =SUMIF(ATB!D:D,CS!B:B,ATB!G:G) -> 0 | F22: =SUMIF(ATB!D:D,CS!B:B,ATB!H:H)+SUMIF(ATB!D:D,CS!B:B,ATB!J:J) -> 0 | G22: =SUMIF(ATB!D:D,CS!B:B,ATB!I:I)+SUMIF(ATB!D:D,CS!B:B,ATB!K:K) -> 0 | H22: =SUMIF(ATB!D:D,CS!B:B,ATB!L:L) -> 0 | I22: =SUMIF(ATB!D:D,CS!B:B,ATB!M:M) -> 0
D23: =SUMIF(ATB!D:D,CS!B:B,ATB!F:F) -> 0 | E23: =SUMIF(ATB!D:D,CS!B:B,ATB!G:G) -> 0 | F23: =SUMIF(ATB!D:D,CS!B:B,ATB!H:H)+SUMIF(ATB!D:D,CS!B:B,ATB!J:J) -> 0 | G23: =SUMIF(ATB!D:D,CS!B:B,ATB!I:I)+SUMIF(ATB!D:D,CS!B:B,ATB!K:K) -> 0 | H23: =SUMIF(ATB!D:D,CS!B:B,ATB!L:L) -> 0 | I23: =SUMIF(ATB!D:D,CS!B:B,ATB!M:M) -> 0
B24: Investment properties | D24: =SUMIF(ATB!D:D,CS!B:B,ATB!F:F) -> 0 | E24: =SUMIF(ATB!D:D,CS!B:B,ATB!G:G) -> 0 | F24: =SUMIF(ATB!D:D,CS!B:B,ATB!H:H)+SUMIF(ATB!D:D,CS!B:B,ATB!J:J) -> 0 | G24: =SUMIF(ATB!D:D,CS!B:B,ATB!I:I)+SUMIF(ATB!D:D,CS!B:B,ATB!K:K) -> 0 | H24: =SUMIF(ATB!D:D,CS!B:B,ATB!L:L) -> 0 | I24: =SUMIF(ATB!D:D,CS!B:B,ATB!M:M) -> 0
D25: =SUMIF(ATB!D:D,CS!B:B,ATB!F:F) -> 0 | E25: =SUMIF(ATB!D:D,CS!B:B,ATB!G:G) -> 0 | F25: =SUMIF(ATB!D:D,CS!B:B,ATB!H:H)+SUMIF(ATB!D:D,CS!B:B,ATB!J:J) -> 0 | G25: =SUMIF(ATB!D:D,CS!B:B,ATB!I:I)+SUMIF(ATB!D:D,CS!B:B,ATB!K:K) -> 0 | H25: =SUMIF(ATB!D:D,CS!B:B,ATB!L:L) -> 0 | I25: =SUMIF(ATB!D:D,CS!B:B,ATB!M:M) -> 0
D26: =SUMIF(ATB!D:D,CS!B:B,ATB!F:F) -> 0 | E26: =SUMIF(ATB!D:D,CS!B:B,ATB!G:G) -> 0 | F26: =SUMIF(ATB!D:D,CS!B:B,ATB!H:H)+SUMIF(ATB!D:D,CS!B:B,ATB!J:J) -> 0 | G26: =SUMIF(ATB!D:D,CS!B:B,ATB!I:I)+SUMIF(ATB!D:D,CS!B:B,ATB!K:K) -> 0 | H26: =SUMIF(ATB!D:D,CS!B:B,ATB!L:L) -> 0 | I26: =SUMIF(ATB!D:D,CS!B:B,ATB!M:M) -> 0
D27: =SUMIF(ATB!D:D,CS!B:B,ATB!F:F) -> 0 | E27: =SUMIF(ATB!D:D,CS!B:B,ATB!G:G) -> 0 | F27: =SUMIF(ATB!D:D,CS!B:B,ATB!H:H)+SUMIF(ATB!D:D,CS!B:B,ATB!J:J) -> 0 | G27: =SUMIF(ATB!D:D,CS!B:B,ATB!I:I)+SUMIF(ATB!D:D,CS!B:B,ATB!K:K) -> 0 | H27: =SUMIF(ATB!D:D,CS!B:B,ATB!L:L) -> 0 | I27: =SUMIF(ATB!D:D,CS!B:B,ATB!M:M) -> 0
B28: Intangible assets | D28: =SUMIF(ATB!D:D,CS!B:B,ATB!F:F) -> 0 | E28: =SUMIF(ATB!D:D,CS!B:B,ATB!G:G) -> 0 | F28: =SUMIF(ATB!D:D,CS!B:B,ATB!H:H)+SUMIF(ATB!D:D,CS!B:B,ATB!J:J) -> 0 | G28: =SUMIF(ATB!D:D,CS!B:B,ATB!I:I)+SUMIF(ATB!D:D,CS!B:B,ATB!K:K) -> 0 | H28: =SUMIF(ATB!D:D,CS!B:B,ATB!L:L) -> 0 | I28: =SUMIF(ATB!D:D,CS!B:B,ATB!M:M) -> 0
D29: =SUMIF(ATB!D:D,CS!B:B,ATB!F:F) -> 0 | E29: =SUMIF(ATB!D:D,CS!B:B,ATB!G:G) -> 0 | F29: =SUMIF(ATB!D:D,CS!B:B,ATB!H:H)+SUMIF(ATB!D:D,CS!B:B,ATB!J:J) -> 0 | G29: =SUMIF(ATB!D:D,CS!B:B,ATB!I:I)+SUMIF(ATB!D:D,CS!B:B,ATB!K:K) -> 0 | H29: =SUMIF(ATB!D:D,CS!B:B,ATB!L:L) -> 0 | I29: =SUMIF(ATB!D:D,CS!B:B,ATB!M:M) -> 0
D30: =SUMIF(ATB!D:D,CS!B:B,ATB!F:F) -> 0 | E30: =SUMIF(ATB!D:D,CS!B:B,ATB!G:G) -> 0 | F30: =SUMIF(ATB!D:D,CS!B:B,ATB!H:H)+SUMIF(ATB!D:D,CS!B:B,ATB!J:J) -> 0 | G30: =SUMIF(ATB!D:D,CS!B:B,ATB!I:I)+SUMIF(ATB!D:D,CS!B:B,ATB!K:K) -> 0 | H30: =SUMIF(ATB!D:D,CS!B:B,ATB!L:L) -> 0 | I30: =SUMIF(ATB!D:D,CS!B:B,ATB!M:M) -> 0
D31: =SUMIF(ATB!D:D,CS!B:B,ATB!F:F) -> 0 | E31: =SUMIF(ATB!D:D,CS!B:B,ATB!G:G) -> 0 | F31: =SUMIF(ATB!D:D,CS!B:B,ATB!H:H)+SUMIF(ATB!D:D,CS!B:B,ATB!J:J) -> 0 | G31: =SUMIF(ATB!D:D,CS!B:B,ATB!I:I)+SUMIF(ATB!D:D,CS!B:B,ATB!K:K) -> 0 | H31: =SUMIF(ATB!D:D,CS!B:B,ATB!L:L) -> 0 | I31: =SUMIF(ATB!D:D,CS!B:B,ATB!M:M) -> 0
B32: Deferred tax assets | D32: =SUMIF(ATB!D:D,CS!B:B,ATB!F:F) -> 0 | E32: =SUMIF(ATB!D:D,CS!B:B,ATB!G:G) -> 0 | F32: =SUMIF(ATB!D:D,CS!B:B,ATB!H:H)+SUMIF(ATB!D:D,CS!B:B,ATB!J:J) -> 0 | G32: =SUMIF(ATB!D:D,CS!B:B,ATB!I:I)+SUMIF(ATB!D:D,CS!B:B,ATB!K:K) -> 0 | H32: =SUMIF(ATB!D:D,CS!B:B,ATB!L:L) -> 0 | I32: =SUMIF(ATB!D:D,CS!B:B,ATB!M:M) -> 0
D33: =SUMIF(ATB!D:D,CS!B:B,ATB!F:F) -> 0 | E33: =SUMIF(ATB!D:D,CS!B:B,ATB!G:G) -> 0 | F33: =SUMIF(ATB!D:D,CS!B:B,ATB!H:H)+SUMIF(ATB!D:D,CS!B:B,ATB!J:J) -> 0 | G33: =SUMIF(ATB!D:D,CS!B:B,ATB!I:I)+SUMIF(ATB!D:D,CS!B:B,ATB!K:K) -> 0 | H33: =SUMIF(ATB!D:D,CS!B:B,ATB!L:L) -> 0 | I33: =SUMIF(ATB!D:D,CS!B:B,ATB!M:M) -> 0
D34: =SUMIF(ATB!D:D,CS!B:B,ATB!F:F) -> 0 | E34: =SUMIF(ATB!D:D,CS!B:B,ATB!G:G) -> 0 | F34: =SUMIF(ATB!D:D,CS!B:B,ATB!H:H)+SUMIF(ATB!D:D,CS!B:B,ATB!J:J) -> 0 | G34: =SUMIF(ATB!D:D,CS!B:B,ATB!I:I)+SUMIF(ATB!D:D,CS!B:B,ATB!K:K) -> 0 | H34: =SUMIF(ATB!D:D,CS!B:B,ATB!L:L) -> 0 | I34: =SUMIF(ATB!D:D,CS!B:B,ATB!M:M) -> 0
D35: =SUMIF(ATB!D:D,CS!B:B,ATB!F:F) -> 0 | E35: =SUMIF(ATB!D:D,CS!B:B,ATB!G:G) -> 0 | F35: =SUMIF(ATB!D:D,CS!B:B,ATB!H:H)+SUMIF(ATB!D:D,CS!B:B,ATB!J:J) -> 0 | G35: =SUMIF(ATB!D:D,CS!B:B,ATB!I:I)+SUMIF(ATB!D:D,CS!B:B,ATB!K:K) -> 0 | H35: =SUMIF(ATB!D:D,CS!B:B,ATB!L:L) -> 0 | I35: =SUMIF(ATB!D:D,CS!B:B,ATB!M:M) -> 0
B36: Held-to-maturity investments | D36: =SUMIF(ATB!D:D,CS!B:B,ATB!F:F) -> 0 | E36: =SUMIF(ATB!D:D,CS!B:B,ATB!G:G) -> 0 | F36: =SUMIF(ATB!D:D,CS!B:B,ATB!H:H)+SUMIF(ATB!D:D,CS!B:B,ATB!J:J) -> 0 | G36: =SUMIF(ATB!D:D,CS!B:B,ATB!I:I)+SUMIF(ATB!D:D,CS!B:B,ATB!K:K) -> 0 | H36: =SUMIF(ATB!D:D,CS!B:B,ATB!L:L) -> 0 | I36: =SUMIF(ATB!D:D,CS!B:B,ATB!M:M) -> 0
B37: Debentures - NCA | D37: =SUMIF(ATB!D:D,CS!B:B,ATB!F:F) -> 0 | E37: =SUMIF(ATB!D:D,CS!B:B,ATB!G:G) -> 0 | F37: =SUMIF(ATB!D:D,CS!B:B,ATB!H:H)+SUMIF(ATB!D:D,CS!B:B,ATB!J:J) -> 0 | G37: =SUMIF(ATB!D:D,CS!B:B,ATB!I:I)+SUMIF(ATB!D:D,CS!B:B,ATB!K:K) -> 0 | H37: =SUMIF(ATB!D:D,CS!B:B,ATB!L:L) -> 0 | I37: =SUMIF(ATB!D:D,CS!B:B,ATB!M:M) -> 0
B38: Zero coupon bonds | D38: =SUMIF(ATB!D:D,CS!B:B,ATB!F:F) -> 0 | E38: =SUMIF(ATB!D:D,CS!B:B,ATB!G:G) -> 0 | F38: =SUMIF(ATB!D:D,CS!B:B,ATB!H:H)+SUMIF(ATB!D:D,CS!B:B,ATB!J:J) -> 0 | G38: =SUMIF(ATB!D:D,CS!B:B,ATB!I:I)+SUMIF(ATB!D:D,CS!B:B,ATB!K:K) -> 0 | H38: =SUMIF(ATB!D:D,CS!B:B,ATB!L:L) -> 0 | I38: =SUMIF(ATB!D:D,CS!B:B,ATB!M:M) -> 0
D39: =SUMIF(ATB!D:D,CS!B:B,ATB!F:F) -> 0 | E39: =SUMIF(ATB!D:D,CS!B:B,ATB!G:G) -> 0 | F39: =SUMIF(ATB!D:D,CS!B:B,ATB!H:H)+SUMIF(ATB!D:D,CS!B:B,ATB!J:J) -> 0 | G39: =SUMIF(ATB!D:D,CS!B:B,ATB!I:I)+SUMIF(ATB!D:D,CS!B:B,ATB!K:K) -> 0 | H39: =SUMIF(ATB!D:D,CS!B:B,ATB!L:L) -> 0 | I39: =SUMIF(ATB!D:D,CS!B:B,ATB!M:M) -> 0
D40: =SUMIF(ATB!D:D,CS!B:B,ATB!F:F) -> 0 | E40: =SUMIF(ATB!D:D,CS!B:B,ATB!G:G) -> 0 | F40: =SUMIF(ATB!D:D,CS!B:B,ATB!H:H)+SUMIF(ATB!D:D,CS!B:B,ATB!J:J) -> 0 | G40: =SUMIF(ATB!D:D,CS!B:B,ATB!I:I)+SUMIF(ATB!D:D,CS!B:B,ATB!K:K) -> 0 | H40: =SUMIF(ATB!D:D,CS!B:B,ATB!L:L) -> 0 | I40: =SUMIF(ATB!D:D,CS!B:B,ATB!M:M) -> 0
D41: =SUMIF(ATB!D:D,CS!B:B,ATB!F:F) -> 0 | E41: =SUMIF(ATB!D:D,CS!B:B,ATB!G:G) -> 0 | F41: =SUMIF(ATB!D:D,CS!B:B,ATB!H:H)+SUMIF(ATB!D:D,CS!B:B,ATB!J:J) -> 0 | G41: =SUMIF(ATB!D:D,CS!B:B,ATB!I:I)+SUMIF(ATB!D:D,CS!B:B,ATB!K:K) -> 0 | H41: =SUMIF(ATB!D:D,CS!B:B,ATB!L:L) -> 0 | I41: =SUMIF(ATB!D:D,CS!B:B,ATB!M:M) -> 0
B42: Available-for-sale financial assets | D42: =SUMIF(ATB!D:D,CS!B:B,ATB!F:F) -> 0 | E42: =SUMIF(ATB!D:D,CS!B:B,ATB!G:G) -> 0 | F42: =SUMIF(ATB!D:D,CS!B:B,ATB!H:H)+SUMIF(ATB!D:D,CS!B:B,ATB!J:J) -> 0 | G42: =SUMIF(ATB!D:D,CS!B:B,ATB!I:I)+SUMIF(ATB!D:D,CS!B:B,ATB!K:K) -> 0 | H42: =SUMIF(ATB!D:D,CS!B:B,ATB!L:L) -> 0 | I42: =SUMIF(ATB!D:D,CS!B:B,ATB!M:M) -> 0
...

Sheet ATB
B1: =Cover!C1 -> ABC LIMITED
B2: ADJUSTED TRAIL BALANCE
B3: =Cover!C3 -> FOR THE YEAR ENDED JUNE 30, 2023
G5: =F6-G6 -> 0 | I5: =H6-I6 -> 0 | K5: =J6-K6 -> 0 | M5: =L6-M6 -> 0
F6: =F1993 -> 0 | G6: =G1993 -> 0 | H6: =H1993 -> 0 | I6: =I1993 -> 0 | J6: =J1993 -> 0 | K6: =K1993 -> 0 | L6: =L1993 -> 0 | M6: =M1993 -> 0
B7: Account Code | C7: Head of Account | D7: Mapping | F7: Opening Balances | H7: Activity during the year | J7: Adjustments | L7: Closing Balances
F8: Debit | G8: Credit | H8: Debit | I8: Credit | J8: Debit | K8: Credit | L8: Debit | M8: Credit
M10: =-ROUND(IF(F10+H10+J10-G10-I10-K10<0,F10+H10+J10-G10-I10-K10,0),0) -> 0
M11: =-ROUND(IF(F11+H11+J11-G11-I11-K11<0,F11+H11+J11-G11-I11-K11,0),0) -> 0
M12: =-ROUND(IF(F12+H12+J12-G12-I12-K12<0,F12+H12+J12-G12-I12-K12,0),0) -> 0
M13: =-ROUND(IF(F13+H13+J13-G13-I13-K13<0,F13+H13+J13-G13-I13-K13,0),0) -> 0
M14: =-ROUND(IF(F14+H14+J14-G14-I14-K14<0,F14+H14+J14-G14-I14-K14,0),0) -> 0
M15: =-ROUND(IF(F15+H15+J15-G15-I15-K15<0,F15+H15+J15-G15-I15-K15,0),0) -> 0
M16: =-ROUND(IF(F16+H16+J16-G16-I16-K16<0,F16+H16+J16-G16-I16-K16,0),0) -> 0
M17: =-ROUND(IF(F17+H17+J17-G17-I17-K17<0,F17+H17+J17-G17-I17-K17,0),0) -> 0
M18: =-ROUND(IF(F18+H18+J18-G18-I18-K18<0,F18+H18+J18-G18-I18-K18,0),0) -> 0
M19: =-ROUND(IF(F19+H19+J19-G19-I19-K19<0,F19+H19+J19-G19-I19-K19,0),0) -> 0
M20: =-ROUND(IF(F20+H20+J20-G20-I20-K20<0,F20+H20+J20-G20-I20-K20,0),0) -> 0
M21: =-ROUND(IF(F21+H21+J21-G21-I21-K21<0,F21+H21+J21-G21-I21-K21,0),0) -> 0
... M97: =-ROUND(IF(F97+H97+J97-G97-I97-K97<0,F97+H97+J97-G97-I97-K97,0),0) -> 0
K98: =SUMIF(AE!C:C,ATB!C:C,AE!F:F) -> 0 | L98: =ROUND(IF(F98+H98+J98-G98-I98-K98>0,F98+H98+J98-G98-I98-K98,0),0) -> 0 | M98: =-ROUND(IF(F98+H98+J98-G98-I98-K98<0,F98+H98+J98-G98-I98-K98,0),0) -> 0
K99: =SUMIF(AE!C:C,ATB!C:C,AE!F:F) -> 0 | L99: =ROUND(IF(F99+H99+J99-G99-I99-K99>0,F99+H99+J99-G99-I99-K99,0),0) -> 0 | M99: =-ROUND(IF(F99+H99+J99-G99-I99-K99<0,F99+H99+J99-G99-I99-K99,0),0) -> 0
K100: =SUMIF(AE!C:C,ATB!C:C,AE!F:F) -> 0 | L100: =ROUND(IF(F100+H100+J100-G100-I100-K100>0,F100+H100+J100-G100-I100-K100,0),0) -> 0 | M100: =-ROUND(IF(F100+H100+J100-G100-I100-K100<0,F100+H100+J100-G100-I100-K100,0),0) -> 0
K101: =SUMIF(AE!C:C,ATB!C:C,AE!F:F) -> 0 | L101: =ROUND(IF(F101+H101+J101-G101-I101-K101>0,F101+H101+J101-G101-I101-K101,0),0) -> 0 | M101: =-ROUND(IF(F101+H101+J101-G101-I101-K101<0,F101+H101+J101-G101-I101-K101,0),0) -> 0
K102: =SUMIF(AE!C:C,ATB!C:C,AE!F:F) -> 0 | L102: =ROUND(IF(F102+H102+J102-G102-I102-K102>0,F102+H102+J102-G102-I102-K102,0),0) -> 0 | M102: =-ROUND(IF(F102+H102+J102-G102-I102-K102<0,F102+H102+J102-G102-I102-K102,0),0) -> 0
K103: =SUMIF(AE!C:C,ATB!C:C,AE!F:F) -> 0 | L103: =ROUND(IF(F103+H103+J103-G103-I103-K103>0,F103+H103+J103-G103-I103-K103,0),0) -> 0 | M103: =-ROUND(IF(F103+H103+J103-G103-I103-K103<0,F103+H103+J103-G103-I103-K103,0),0) -> 0
K104: =SUMIF(AE!C:C,ATB!C:C,AE!F:F) -> 0 | L104: =ROUND(IF(F104+H104+J104-G104-I104-K104>0,F104+H104+J104-G104-I104-K104,0),0) -> 0 | M104: =-ROUND(IF(F104+H104+J104-G104-I104-K104<0,F104+H104+J104-G104-I104-K104,0),0) -> 0
K105: =SUMIF(AE!C:C,ATB!C:C,AE!F:F) -> 0 | L105: =ROUND(IF(F105+H105+J105-G105-I105-K105>0,F105+H105+J105-G105-I105-K105,0),0) -> 0 | M105: =-ROUND(IF(F105+H105+J105-G105-I105-K105<0,F105+H105+J105-G105-I105-K105,0),0) -> 0
K106: =SUMIF(AE!C:C,ATB!C:C,AE!F:F) -> 0 | L106: =ROUND(IF(F106+H106+J106-G106-I106-K106>0,F106+H106+J106-G106-I106-K106,0),0) -> 0 | M106: =-ROUND(IF(F106+H106+J106-G106-I106-K106<0,F106+H106+J106-G106-I106-K106,0),0) -> 0
K107: =SUMIF(AE!C:C,ATB!C:C,AE!F:F) -> 0 | L107: =ROUND(IF(F107+H107+J107-G107-I107-K107>0,F107+H107+J107-G107-I107-K107,0),0) -> 0 | M107: =-ROUND(IF(F107+H107+J107-G107-I107-K107<0,F107+H107+J107-G107-I107-K107,0),0) -> 0
K108: =SUMIF(AE!C:C,ATB!C:C,AE!F:F) -> 0 | L108: =ROUND(IF(F108+H108+J108-G108-I108-K108>0,F108+H108+J108-G108-I108-K108,0),0) -> 0 | M108: =-ROUND(IF(F108+H108+J108-G108-I108-K108<0,F108+H108+J108-G108-I108-K108,0),0) -> 0
K109: =SUMIF(AE!C:C,ATB!C:C,AE!F:F) -> 0 | L109: =ROUND(IF(F109+H109+J109-G109-I109-K109>0,F109+H109+J109-G109-I109-K109,0),0) -> 0 | M109: =-ROUND(IF(F109+H109+J109-G109-I109-K109<0,F109+H109+J109-G109-I109-K109,0),0) -> 0
... K1991: =SUMIF(AE!C:C,ATB!C:C,AE!F:F) -> 0 | L1991: =ROUND(IF(F1991+H1991+J1991-G1991-I1991-K1991>0,F1991+H1991+J1991-G1991-I1991-K1991,0),0) -> 0 | M1991: =-ROUND(IF(F1991+H1991+J1991-G1991-I1991-K1991<0,F1991+H1991+J1991-G1991-I1991-K1991,0),0) -> 0
F1993: =SUM(F9:F1992) -> 0 | G1993: =SUM(G9:G1992) -> 0 | H1993: =SUM(H9:H1992) -> 0 | I1993: =SUM(I9:I1992) -> 0 | J1993: =SUM(J9:J1992) -> 0 | K1993: =SUM(K9:K1992) -> 0 | L1993: =SUM(L9:L1992) -> 0 | M1993: =SUM(M9:M1992) -> 0
G1994: =F1993-G1993 -> 0 | I1994: =H1993-I1993 -> 0 | K1994: =J1993-K1993 -> 0 | M1994: =L1993-M1993 -> 0

Sheet AE
A1: =Cover!C1 -> ABC LIMITED
A2: ADJUSTING ENTRIES
A3: =Cover!C3 -> FOR THE YEAR ENDED JUNE 30, 2023
A5: Sr. # | B5: Account Code | C5: Head of Account / Description | E5: Amount
E6: Debit | F6: Credit
E2000: =SUM(E7:E1999) -> 0 | F2000: =SUM(F7:F1999) -> 0

Sheet AD
B1: =Cover!C1 -> ABC LIMITED
B2: ACCOUNTING DEPRECIATION & DISPOSALS WORKING
B3: =Cover!C3 -> FOR THE YEAR ENDED JUNE 30, 2023
B5: Depreciation Working
B7: Asset Type | C7: Description | D7: Date | E7: Opening WDV | F7: Additions | G7: Total Assets | H7: Number of Month in use | I7: Depreciation Rate | J7: Depreciation Charge | K7: Total Depreciation | L7: Closing WDV
B10: =FAS!H15 -> Freehold Land | C10: Opening Balance | D10: =Cover!$I$6 -> 44743 | E10: =FAS!H64 -> 0 | G10: =E10+F10 -> 0 | H10: =IF(YEAR(D10)=2022,19-MONTH(D10),IF(YEAR(D10)=2023,7-MONTH(D10),IF(D10="","","Date Error"))) -> 12 | I10: =FAS!H62 -> 0 | J10: =IF(G10=0,0,-G10*H10*I10/12) -> 0
G11: =E11+F11 -> 0 | H11: =IF(YEAR(D11)=2022,19-MONTH(D11),IF(YEAR(D11)=2023,7-MONTH(D11),IF(D11="","","Date Error"))) | I11: =IF(H11="","",I10) | J11: =IF(G11=0,0,-G11*H11*I11/12) -> 0
G12: =E12+F12 -> 0 | H12: =IF(YEAR(D12)=2022,19-MONTH(D12),IF(YEAR(D12)=2023,7-MONTH(D12),IF(D12="","","Date Error"))) | I12: =IF(H12="","",I11) | J12: =IF(G12=0,0,-G12*H12*I12/12) -> 0
B13: Disposal | G13: =-O69 -> 0 | J13: =R69 -> 0
K14: =ROUND(SUM(J10:J14),0) -> 0 | L14: =SUM(G10:G14)+K14 -> 0
B15: =FAS!J15 -> Building on Freehold Land | C15: Opening Balance | D15: =Cover!$I$6 -> 44743 | E15: =FAS!J64 -> 0 | G15: =E15+F15 -> 0 | H15: =IF(YEAR(D15)=2022,19-MONTH(D15),IF(YEAR(D15)=2023,7-MONTH(D15),IF(D15="","","Date Error"))) -> 12 | I15: =FAS!J62 -> 0 | J15: =IF(G15=0,0,-G15*H15*I15/12) -> 0
G16: =E16+F16 -> 0 | H16: =IF(YEAR(D16)=2022,19-MONTH(D16),IF(YEAR(D16)=2023,7-MONTH(D16),IF(D16="","","Date Error"))) | I16: =IF(H16="","",I15) | J16: =IF(G16=0,0,-G16*H16*I16/12) -> 0
G17: =E17+F17 -> 0 | H17: =IF(YEAR(D17)=2022,19-MONTH(D17),IF(YEAR(D17)=2023,7-MONTH(D17),IF(D17="","","Date Error"))) | J17: =IF(G17=0,0,-G17*H17*I17/12) -> 0
B18: Disposal | G18: =-O73 -> 0 | J18: =R73 -> 0
K19: =ROUND(SUM(J15:J19),0) -> 0 | L19: =SUM(G15:G19)+K19 -> 0
B20: =FAS!L15 -> Plant and Machinery | C20: Opening Balance | D20: =Cover!$I$6 -> 44743 | E20: =FAS!L64 -> 0 | G20: =E20+F20 -> 0 | H20: =IF(YEAR(D20)=2022,19-MONTH(D20),IF(YEAR(D20)=2023,7-MONTH(D20),IF(D20="","","Date Error"))) -> 12 | I20: =FAS!L62 -> 0 | J20: =IF(G20=0,0,-G20*H20*I20/12) -> 0
G21: =E21+F21 -> 0 | H21: =IF(YEAR(D21)=2022,19-MONTH(D21),IF(YEAR(D21)=2023,7-MONTH(D21),IF(D21="","","Date Error"))) | I21: =IF(H21="","",I20) | J21: =IF(G21=0,0,-G21*H21*I21/12) -> 0
G22: =E22+F22 -> 0 | H22: =IF(YEAR(D22)=2022,19-MONTH(D22),IF(YEAR(D22)=2023,7-MONTH(D22),IF(D22="","","Date Error"))) | I22: =IF(H22="","",I21) | J22: =IF(G22=0,0,-G22*H22*I22/12) -> 0
B23: Disposal | G23: =-O77 -> 0 | J23: =R77 -> 0
K24: =ROUND(SUM(J20:J24),0) -> 0 | L24: =SUM(G20:G24)+K24 -> 0
B25: =FAS!N15 -> Generator | C25: Opening Balance | D25: =Cover!$I$6 -> 44743 | E25: =FAS!N64 -> 0 | G25: =E25+F25 -> 0 | H25: =IF(YEAR(D25)=2022,19-MONTH(D25),IF(YEAR(D25)=2023,7-MONTH(D25),IF(D25="","","Date Error"))) -> 12 | I25: =FAS!N62 -> 0 | J25: =IF(G25=0,0,-G25*H25*I25/12) -> 0
G26: =E26+F26 -> 0 | H26: =IF(YEAR(D26)=2022,19-MONTH(D26),IF(YEAR(D26)=2023,7-MONTH(D26),IF(D26="","","Date Error"))) | I26: =IF(H26="","",I25) | J26: =IF(G26=0,0,-G26*H26*I26/12) -> 0
G27: =E27+F27 -> 0 | H27: =IF(YEAR(D27)=2022,19-MONTH(D27),IF(YEAR(D27)=2023,7-MONTH(D27),IF(D27="","","Date Error"))) | I27: =IF(H27="","",I26) | J27: =IF(G27=0,0,-G27*H27*I27/12) -> 0
B28: Disposal | G28: =-O81 -> 0 | J28: =R81 -> 0
K29: =ROUND(SUM(J25:J29),0) -> 0 | L29: =SUM(G25:G29)+K29 -> 0
B30: =FAS!P15 -> Office Equipment | C30: Opening Balance | D30: =Cover!$I$6 -> 44743 | E30: =FAS!P64 -> 0 | G30: =E30+F30 -> 0 | H30: =IF(YEAR(D30)=2022,19-MONTH(D30),IF(YEAR(D30)=2023,7-MONTH(D30),IF(D30="","","Date Error"))) -> 12 | I30: =FAS!P62 -> 0 | J30: =IF(G30=0,0,-G30*H30*I30/12) -> 0
G31: =E31+F31 -> 0 | H31: =IF(YEAR(D31)=2022,19-MONTH(D31),IF(YEAR(D31)=2023,7-MONTH(D31),IF(D31="","","Date Error"))) | I31: =IF(H31="","",I30) | J31: =IF(G31=0,0,-G31*H31*I31/12) -> 0
G32: =E32+F32 -> 0 | H32: =IF(YEAR(D32)=2022,19-MONTH(D32),IF(YEAR(D32)=2023,7-MONTH(D32),IF(D32="","","Date Error"))) | I32: =IF(H32="","",I31) | J32: =IF(G32=0,0,-G32*H32*I32/12) -> 0
B33: Disposal | G33: =-O85 -> 0 | J33: =R85 -> 0
K34: =ROUND(SUM(J30:J34),0) -> 0 | L34: =SUM(G30:G34)+K34 -> 0
B35: =FAS!R15 -> Computers | C35: Opening Balance | D35: =Cover!$I$6 -> 44743 | E35: =FAS!R64 -> 0 | G35: =E35+F35 -> 0 | H35: =IF(YEAR(D35)=2022,19-MONTH(D35),IF(YEAR(D35)=2023,7-MONTH(D35),IF(D35="","","Date Error"))) -> 12 | I35: =FAS!R62 -> 0 | J35: =IF(G35=0,0,-G35*H35*I35/12) -> 0
G36: =E36+F36 -> 0 | H36: =IF(YEAR(D36)=2022,19-MONTH(D36),IF(YEAR(D36)=2023,7-MONTH(D36),IF(D36="","","Date Error"))) | I36: =IF(H36="","",I35) | J36: =IF(G36=0,0,-G36*H36*I36/12) -> 0
G37: =E37+F37 -> 0 | H37: =IF(YEAR(D37)=2022,19-MONTH(D37),IF(YEAR(D37)=2023,7-MONTH(D37),IF(D37="","","Date Error"))) | I37: =IF(H37="","",I36) | J37: =IF(G37=0,0,-G37*H37*I37/12) -> 0
B38: Disposal | G38: =-O89 -> 0 | J38: =R89 -> 0
K39: =ROUND(SUM(J35:J39),0) -> 0 | L39: =SUM(G35:G39)+K39 -> 0
B40: =FAS!T15 -> Electric Equipment & Installations | C40: Opening Balance | D40: =Cover!$I$6 -> 44743 | E40: =FAS!T64 -> 0 | G40: =E40+F40 -> 0 | H40: =IF(YEAR(D40)=2022,19-MONTH(D40),IF(YEAR(D40)=2023,7-MONTH(D40),IF(D40="","","Date Error"))) -> 12 | I40: =FAS!T62 -> 0 | J40: =IF(G40=0,0,-G40*H40*I40/12) -> 0
G41: =E41+F41 -> 0 | H41: =IF(YEAR(D41)=2022,19-MONTH(D41),IF(YEAR(D41)=2023,7-MONTH(D41),IF(D41="","","Date Error"))) | I41: =IF(H41="","",I40) | J41: =IF(G41=0,0,-G41*H41*I41/12) -> 0
G42: =E42+F42 -> 0 | H42: =IF(YEAR(D42)=2022,19-MONTH(D42),IF(YEAR(D42)=2023,7-MONTH(D42),IF(D42="","","Date Error"))) | I42: =IF(H42="","",I41) | J42: =IF(G42=0,0,-G42*H42*I42/12) -> 0
B43: Disposal | G43: =-O93 -> 0 | J43: =R93 -> 0
K44: =ROUND(SUM(J40:J44),0) -> 0 | L44: =SUM(G40:G44)+K44 -> 0
...

Sheet TD
A1: =Cover!C1 -> ABC LIMITED
A2: TAX DEPRECIATION
A3: =Cover!C3 -> FOR THE YEAR ENDED JUNE 30, 2023
A5: Description | B5: Opening WDV | C5: Additions | D5: Deletions | E5: Total | F5: Initial Allowance | H5: Depreciation | J5: Total Depreciation | K5: Closing WDV
F6: Rate % | G6: Amount | H6: Rate % | I6: Amount
A8: Building | E8: =SUM(B8:D8) -> 0 | F8: 0 | G8: =C8*F8 -> 0 | H8: 0.1 | I8: =(E8-G8)*H8 -> 0 | J8: =G8+I8 -> 0 | K8: =E8-J8 -> 0
A9: Plant and machinery | E9: =SUM(B9:D9) -> 0 | F9: 0.25 | G9: =C9*F9 -> 0 | H9: 0.15 | I9: =(E9-G9)*H9 -> 0 | J9: =G9+I9 -> 0 | K9: =E9-J9 -> 0
A10: Motor vehicles | E10: =SUM(B10:D10) -> 0 | F10: 0 | G10: =C10*F10 -> 0 | H10: 0.15 | I10: =(E10-G10)*H10 -> 0 | J10: =G10+I10 -> 0 | K10: =E10-J10 -> 0
A11: Furniture and fixtures | E11: =SUM(B11:D11) -> 0 | F11: 0 | G11: =C11*F11 -> 0 | H11: 0.15 | I11: =(E11-G11)*H11 -> 0 | J11: =G11+I11 -> 0 | K11: =E11-J11 -> 0
A12: Computers | E12: =SUM(B12:D12) -> 0 | F12: 0 | G12: =C12*F12 -> 0 | H12: 0.3 | I12: =(E12-G12)*H12 -> 0 | J12: =G12+I12 -> 0 | K12: =E12-J12 -> 0
A14: Total | B14: =SUM(B7:B13) -> 0 | C14: =SUM(C7:C13) -> 0 | D14: =SUM(D7:D13) -> 0 | E14: =SUM(E7:E13) -> 0 | G14: =SUM(G7:G13) -> 0 | I14: =SUM(I7:I13) -> 0 | J14: =SUM(J7:J13) -> 0 | K14: =SUM(K7:K13) -> 0
A17: Description | B17: Opening Cost | C17: Opening Amortization | D17: Opening WDV | E17: Additions | F17: Deletions | G17: Total | H17: Useful Life | I17: Amortization | J17: Total Amortization | K17: Closing WDV
C18: Amount | D18: Amount | H18: Years | I18: Amount
A20: Financial software | B20: 0 | C20: 0 | D20: =B20-C20 -> 0 | E20: 0 | F20: 0 | G20: =SUM(D20:F20) -> 0 | H20: 10 | I20: =B20/H20 -> 0 | J20: =C20+I20 -> 0 | K20: =G20-I20 -> 0
A22: Total | B22: =SUM(B19:B21) -> 0 | C22: =SUM(C19:C21) -> 0 | D22: =SUM(D19:D21) -> 0 | E22: =SUM(E19:E21) -> 0 | F22: =SUM(F19:F21) -> 0 | G22: =SUM(G19:G21) -> 0 | I22: =SUM(I19:I21) -> 0 | J22: =SUM(J19:J21) -> 0 | K22: =SUM(K19:K21) -> 0
A26: Asset Type | B26: Description | C26: Date of Acquisition | D26: Date of Disposal | E26: Cost | F26: Depreciation Rate | G26: Number of Years in use (Previous Years) | H26: Net Book Value | I26: Sales Proceeds | J26: Tax Gain / (Loss) on Disposals
A28: =IF(AD!B66=0,"",AD!B66) -> Freehold Land | B28: =IF(AD!C66=0,"",AD!C66) | C28: =IF(B28="","",AD!D66) | D28: =IF(B28="","",AD!E66) | E28: =IF(B28="","",AD!I66) | F28: 0 | G28: =YEAR(D28)-YEAR(C28) -> #VALUE! | I28: =IF(B28="",0,AD!P66) -> 0 | J28: =I28-H28 -> 0
A29: =IF(AD!B67=0,"",AD!B67) | B29: =IF(AD!C67=0,"",AD!C67) | C29: =IF(B29="","",AD!D67) | D29: =IF(B29="","",AD!E67) | E29: =IF(B29="","",AD!I67) | F29: 0 | G29: =YEAR(D29)-YEAR(C29) -> #VALUE! | I29: =IF(B29="",0,AD!P67) -> 0 | J29: =I29-H29 -> 0
A30: =IF(AD!B68=0,"",AD!B68) | B30: =IF(AD!C68=0,"",AD!C68) | C30: =IF(B30="","",AD!D68) | D30: =IF(B30="","",AD!E68) | E30: =IF(B30="","",AD!I68) | F30: 0 | G30: =YEAR(D30)-YEAR(C30) -> #VALUE! | I30: =IF(B30="",0,AD!P68) -> 0 | J30: =I30-H30 -> 0
A31: =IF(AD!B69=0,"",AD!B69) | B31: =IF(AD!C69=0,"",AD!C69) | C31: =IF(B31="","",AD!D69) | D31: =IF(B31="","",AD!E69) | E31: =IF(B31="","",AD!I69) | I31: =IF(B31="",0,AD!P69) -> 0 | J31: =I31-H31 -> 0
A32: =IF(AD!B70=0,"",AD!B70) -> Building on Freehold Land | B32: =IF(AD!C70=0,"",AD!C70) | C32: =IF(B32="","",AD!D70) | D32: =IF(B32="","",AD!E70) | E32: =IF(B32="","",AD!I70) | F32: =H8 -> 0.1 | G32: =YEAR(D32)-YEAR(C32) -> #VALUE! | I32: =IF(B32="",0,AD!P70) -> 0 | J32: =I32-H32 -> 0
A33: =IF(AD!B71=0,"",AD!B71) | B33: =IF(AD!C71=0,"",AD!C71) | C33: =IF(B33="","",AD!D71) | D33: =IF(B33="","",AD!E71) | E33: =IF(B33="","",AD!I71) | F33: =F32 -> 0.1 | G33: =YEAR(D33)-YEAR(C33) -> #VALUE! | I33: =IF(B33="",0,AD!P71) -> 0 | J33: =I33-H33 -> 0
A34: =IF(AD!B72=0,"",AD!B72) | B34: =IF(AD!C72=0,"",AD!C72) | C34: =IF(B34="","",AD!D72) | D34: =IF(B34="","",AD!E72) | E34: =IF(B34="","",AD!I72) | F34: =F33 -> 0.1 | G34: =YEAR(D34)-YEAR(C34) -> #VALUE! | I34: =IF(B34="",0,AD!P72) -> 0 | J34: =I34-H34 -> 0
