Workbook
Name ___B99999: #REF!
Name ___B99999: #REF!
Name ___B99999: #REF!
Name ___B99999: #REF!
Name ___B99999: #REF!
Name ___B99999: #REF!
Name ___B99999: #REF!
Name ___B99999: #REF!
Name __B99999: #REF!
Name __B99999: #REF!
Name __B99999: #REF!
Name __B99999: #REF!
Name __B99999: #REF!
Name __B99999: #REF!
Name __B99999: #REF!
Name __B99999: #REF!
Name _B99999: #REF!
Name _B99999: #REF!
Name _B99999: #REF!
Name _B99999: #REF!
Name _B99999: #REF!
Name _B99999: #REF!
Name _B99999: #REF!
Name _B99999: #REF!

Sheet Index
A1: ABC & Co.
A2: (Chartered Accountants)
A5: INDEX OF CASH COUNT, STOCK TAKE AND FIXED ASSETS VERIFICATION FILE
A8: SR. # | B8: DESCRIPTION | C8: REF #
A10: =0+1&"." -> 1. | B10: Stock Take Checklist
A11: =A10+1&"." -> 2. | B11: Documents Requisition
A12: =A11+1&"." -> 3. | B12: Cash Count Sheets
A13: =A12+1&"." -> 4. | B13: Stock Take Guideline
A14: =A13+1&"." -> 5. | B14: Inventory Sheets - Received from Client
A15: =A14+1&"." -> 6. | B15: Stores, Spare and Loose Tools - Verification Sheets
A16: =A15+1&"." -> 7. | B16: Cut off - Store and Supporting Documents
A17: =A16+1&"." -> 8. | B17: Cut off - Purchases and Supporting Documents
A18: =A17+1&"." -> 9. | B18: Cut off - Sales and Supporting Documents
A19: =A18+1&"." -> 10. | B19: Cut off - Journal Vouchers
A20: =A19+1&"." -> 11. | B20: Cut off - Bank Payment Vouchers
A21: =A20+1&"." -> 12. | B21: Cut off - Bank Receipt Vouchers
A22: =A21+1&"." -> 13. | B22: Cut off - Cash Payment Vouchers
... A25: =A24+1&"." -> 16. | B25: Fixed Assets Listing - Received from Client

Sheet Checklist
A1: =Index!A1 -> ABC & Co.
A2: =Index!A2 -> (Chartered Accountants)
A4: STOCK TAKE CHECKLIST
B6: Audit Procedures | K6: Performed | L6: Remarks
K7: Yes , No , N/A
B9: The following tasks should be carried out before the physical inventory begins:
C11: Obtain a copy of the client’s inventory instructions.
C12: Review adequacy of instructions using the pre-printed checklist and discuss any weaknesses in instruction with the client.
C15: Arrange for letters to be sent to third parties holding inventories on behalf of client, requesting confirmation of these inventories to be sent direct to the auditors with a copy to the client. The main task during the count to see that the client’s employees are carrying out their instructions properly.
B22: The physical inventory pre-printed checklist should be completed and supporting schedules will be prepared to cover the following:
C25: Notes of inventory movement during the count.
C26: Details of last number prior to physical inventory in respect of:
D28: Goods received
D29: Goods dispatched
D30: Internal movement of goods
B32: Details of numbering of inventory sheets used and destroyed and of control of their issue to and return by those carrying out the physical inventory.
B35: Schedules of items counted by the auditor showing their valuation (this valuation may have to be completed at final visit).
B38: Details of any old, obsolete, damaged or excess inventories noted during the attendance.
B40: Comments on adequacy of custody.
B41: The working paper should be prepared in such a manner that the information can be easily followed up at the final audit visit. Test counts for example should have been traced to the stock sheets to confirm that they are a proper record of the results of the physical inventory.
B48: The auditor should be aware of the approximate value of the various inventory items as he may wish to cover high value items in his test count. The valuation of the items counted by the auditors should be recorded during the count or, if not possible, at the final audit visit.
B54: Where it is considered that physical inventory has been unsatisfactory in any major respect that matter should be reported immediately to the manager or partner concerned so that the necessity for a second physical inventory can be considered and discussed with the client.
B61: At the final audit the information obtained at the physical inventory will be followed up. The work to be carried out will include:
B65: An overall review of the working papers to assess the effectiveness of the physical count and whether the final audit program work should be altered as a result.
B69: A check of the cut-off using the information obtained or the last goods received and dispatched note numbers.
B72: A check of the auditor’s test count items to the final inventory sheets.
B75: A test that the final inventory sheets include only the inventories counted by reference to the details of numbering of inventory sheets obtained during the observation.
... B94: Client ___________________________________________________________

Sheet Documents Requisition
A1: =Index!A1 -> ABC & Co.
A2: =Index!A2 -> (Chartered Accountants)
A4: =UPPER("Documents required for Stock Take") -> DOCUMENTS REQUIRED FOR STOCK TAKE
A6: Client Name
A7: Year Ended
A10: Sr. No. | B10: Particulars | H10: Tick
A14: 1 | B14: Signed Inventory Sheets of:
A15: a. | B15: Stores, Spares and Loose tools
A16: b. | B16: Raw Material
A17: c. | B17: Work in Process
A18: d. | B18: Finished goods
A19: e. | B19: Scrap Items
A20: f. | B20: Waste Stock
A22: 2 | B22: Cut off Documents
A24: 3 | B24: Certificates of:
A25: a. | B25: All Stock declared to Auditors
A26: b. | B26: No Captilized items other than declared
A27: c. | B27: No Obsolete or Slow Moving Items other than declared
A28: d. | B28: No Third party Stocks held by the Company other than declared
A29: e. | B29: No stock of company held by third party other than declared
A30: f. | B30: Cash in hand
A31: g. | B31: IOU's | J31: I owe you.
A32: h. | B32: Pledge Stock Certificate
A33: i. | B33: Stock in transit, if any
A43: Receiver's Signature | F43: Date & Time

Sheet Cash Count Sheet
A1: =Index!A1 -> ABC & Co.
A2: =Index!A2 -> (Chartered Accountants)
A4: CASH COUNT SHEET
A5: Client :
A6: Date of count : | F6: Year ended :
A7: Location : | F7: Time :
A9: CASH COUNT DETAIL
A11: Denomination | C11: Numbers | F11: Amount
A13: 5000 | B13: X | E13: =
A15: 1000 | B15: X | E15: =
A17: 500 | B17: X | E17: =
A19: 100 | B19: X | E19: =
A21: 75 | B21: X | E21: =
A23: 50 | B23: X | E23: =
A25: 20 | B25: X | E25: =
A27: 10 | B27: X | E27: =
A29: 5 | B29: X | E29: =
A31: 2 | B31: X | E31: =
A33: 1 | B33: X | E33: =
A35: Statutory Bonds (Details attached)
A37: Revenue stamps (Details attached)
A39: Cheques (Details attached)
A41: I.O.U.s (Details attached)
A43: Sub total
A45: Adjustment if cash is counted at the date of other than the cut off date (if any)
A49: Grand total
A51: Balance as per cash book
A53: There is no cash in hand except that which is disclosed
A55: Auditors' Signature | F55: For Client
A59: For and on behalf of, | F59: Name:
A60: =A1 -> ABC & Co. | F60: Designation
A61: =PROPER(A2) -> (Chartered Accountants) | F61: Signature

Sheet StockTake Guideline
A1: =Index!A1 -> ABC & Co.
A2: =Index!A2 -> (Chartered Accountants)
A4: STOCK TAKE GUIDELINE
A6: Client Name:
A7: Nature of Business:
A8: Year Ended
A10: Current Year Arrangements
C12: Stock Taking Started On: | K12: No. of Days:
C13: Stock Taking Completed On: | K13: Working Days: | O13: Hours
E14: Supervised By:
E15: Junior(s): 1 | J15: 2 | N15: 3
A17: Last Year Arrangements:
C19: Stock Taking Started On: | K19: No. of Days:
C20: Stock Taking Completed On: | K20: Working Days: | O20: Hours
E21: Supervised By:
A23: Statistics of Stock Checking
G24: % Checked | J24: Places | N24: % Remained Unchecked
B27: Raw Materials:
B28: Work in Process:
B29: Finished Goods:
B30: Wastes:
B31: Stores and Spares:
B32: Obsolete Stores and Spares
B33: Stores held for capital expenditure:
B34: Others:
A37: Instructions: | M37: Yes/No | O37: Remarks
A38: 1- | B38: Have written instructions been given to client staff?
A39: 2- | B39: Has the client already reconciled/counted the stock?
A40: 3- | B40: Does the client's stock checking team have the familiarity with stocks/stores?
A43: Client's Environment:
M44: Yes/No | O44: Remarks
A45: 1- | B45: Whether or not the stocks and stores:
B47: ---- | C47: properly safeguarded:
B48: ---- | C48: in good condition; and
B49: ---- | C49: kept in a systematic manner.
A51: 2- | B51: Whether or not:
B53: ---- | C53: the production areas were ready for checking of work in process;
B54: ---- | C54: the mills were still working at the time of checking; and if yes, how
C55: was the work in process verified.
A57: 3- | B57: Whether or not the followings were included in stocks:
...

Sheet Store Spares and Loose Tools
A1: =Index!A1 -> ABC & Co.
A2: =Index!A2 -> (Chartered Accountants)
A4: =UPPER("Sheet To Floor") -> SHEET TO FLOOR
A6: Sr. # | B6: Product Type & Code | C6: Description | D6: Quantity Observed | E6: Quantity Per Stock Report | F6: Difference
A7: 1
A8: =+A7+1 -> 2
A9: =+A8+1 -> 3
A10: =+A9+1 -> 4
A11: =+A10+1 -> 5
A12: =+A11+1 -> 6
A13: =+A12+1 -> 7
A14: =+A13+1 -> 8
A15: =+A14+1 -> 9
A16: =+A15+1 -> 10
A17: =+A16+1 -> 11
A18: =+A17+1 -> 12
A19: =+A18+1 -> 13
... A31: =+A30+1 -> 25
A34: =A1 -> ABC & Co.
A35: =A2 -> (Chartered Accountants)
A37: =UPPER("Floor to Sheet") -> FLOOR TO SHEET
A39: Sr. # | B39: Product Type & Code | C39: Description | D39: Quantity Observed | E39: Quantity Per Stock Report | F39: Difference
A40: 1
A41: =+A40+1 -> 2
A42: =+A41+1 -> 3
A43: =+A42+1 -> 4
A44: =+A43+1 -> 5
A45: =+A44+1 -> 6
A46: =+A45+1 -> 7
A47: =+A46+1 -> 8
A48: =+A47+1 -> 9
A49: =+A48+1 -> 10
A50: =+A49+1 -> 11
A51: =+A50+1 -> 12
A52: =+A51+1 -> 13
... A64: =+A63+1 -> 25

Sheet Cut off - Store
A1: =Index!A1 -> ABC & Co.
A2: =Index!A2 -> (Chartered Accountants)
A4: CUT OFF PROCEDURES - STORES
A6: Client Name: | E6: Prepared By:
A7: Year Ended: | E7: Reviewed By:
A8: Subject: | E8: Date:
A10: OPENING TRANSACTIONS AS AT 01-07-2022
A12: Date | B12: Voucher # | C12: Demand # | D12: Issuance # | E12: Description | F12: Amount
A20: CLOSING TRANSACTIONS AS AT 30-06-2023
A22: Date | B22: Voucher # | C22: Demand # | D22: Issuance # | E22: Description | F22: Amount
A30: OPENING TRANSACTION - SUBSEQUENT AFTER 30-06-2023
A32: Date | B32: Voucher # | C32: Demand # | D32: Issuance # | E32: Description | F32: Amount
A40: CONCLUSION:

Sheet Cut off - Purchases
A1: =Index!A1 -> ABC & Co.
A2: =Index!A2 -> (Chartered Accountants)
A4: CUT OFF PROCEDURES - PURCHASES
A6: Client Name: | E6: Prepared By:
A7: Year Ended: | E7: Reviewed By:
A8: Subject: | E8: Date:
A10: ='Cut off - Store'!A10:F10 -> OPENING TRANSACTIONS AS AT 01-07-2022
A12: Date | B12: Voucher # | C12: Goods Received Note # | D12: Purchase Invoice # | E12: Description | F12: Amount
A20: ='Cut off - Store'!A20:F20 -> CLOSING TRANSACTIONS AS AT 30-06-2023
A22: Date | B22: Voucher # | C22: Goods Received Note # | D22: Purchase Invoice # | E22: Description | F22: Amount
A30: ='Cut off - Store'!A30:F30 -> OPENING TRANSACTION - SUBSEQUENT AFTER 30-06-2023
A32: Date | B32: Voucher # | C32: Goods Received Note # | D32: Purchase Invoice # | E32: Description | F32: Amount
A40: CONCLUSION:

Sheet Cut off - Sales
A1: =Index!A1 -> ABC & Co.
A2: =Index!A2 -> (Chartered Accountants)
A4: CUT OFF PROCEDURES - SALES
A6: Client Name: | E6: Prepared By:
A7: Year Ended: | E7: Reviewed By:
A8: Subject: | E8: Date:
A10: ='Cut off - Store'!A10:F10 -> OPENING TRANSACTIONS AS AT 01-07-2022
A12: Date | B12: Voucher # | C12: Delivery Challan # | D12: Sales Invoice # | E12: Description | F12: Amount
A20: ='Cut off - Store'!A20:F20 -> CLOSING TRANSACTIONS AS AT 30-06-2023
A22: Date | B22: Voucher # | C22: Delivery Challan # | D22: Sales Invoice # | E22: Description | F22: Amount
A30: ='Cut off - Store'!A30:F30 -> OPENING TRANSACTION - SUBSEQUENT AFTER 30-06-2023
A32: Date | B32: Voucher # | C32: Delivery Challan # | D32: Sales Invoice # | E32: Description | F32: Amount
A40: CONCLUSION:

Sheet Cut off - JV
A1: =Index!A1 -> ABC & Co.
A2: =Index!A2 -> (Chartered Accountants)
A4: CUT OFF PROCEDURES - JOURNAL VOUCHER
A6: Client Name: | E6: Prepared By:
A7: Year Ended: | E7: Reviewed By:
A8: Subject: | E8: Date:
A10: ='Cut off - Store'!A10:F10 -> OPENING TRANSACTIONS AS AT 01-07-2022
A12: Date | B12: Voucher # | C12: Invoice # | D12: Description | F12: Amount
A20: ='Cut off - Store'!A20:F20 -> CLOSING TRANSACTIONS AS AT 30-06-2023
A22: Date | B22: Voucher # | C22: Invoice # | D22: Description | F22: Amount
A30: ='Cut off - Store'!A30:F30 -> OPENING TRANSACTION - SUBSEQUENT AFTER 30-06-2023
A32: Date | B32: Voucher # | C32: Invoice # | D32: Description | F32: Amount
A40: CONCLUSION:

Sheet Cut off - BPV
A1: =Index!A1 -> ABC & Co.
A2: =Index!A2 -> (Chartered Accountants)
A4: CUT OFF PROCEDURES - BANK PAYMENT VOUCHER
A6: Client Name: | E6: Prepared By:
A7: Year Ended: | E7: Reviewed By:
A8: Subject: | E8: Date:
A10: ='Cut off - Store'!A10:F10 -> OPENING TRANSACTIONS AS AT 01-07-2022
A12: Date | B12: Voucher # | C12: Cheque # | D12: Description | F12: Amount
A20: ='Cut off - Store'!A20:F20 -> CLOSING TRANSACTIONS AS AT 30-06-2023
A22: Date | B22: Voucher # | C22: Cheque # | D22: Description | F22: Amount
A30: ='Cut off - Store'!A30:F30 -> OPENING TRANSACTION - SUBSEQUENT AFTER 30-06-2023
A32: Date | B32: Voucher # | C32: Cheque # | D32: Description | F32: Amount
A40: CONCLUSION:

Sheet Cut off - BRV
A1: =Index!A1 -> ABC & Co.
A2: =Index!A2 -> (Chartered Accountants)
A4: CUT OFF PROCEDURES - BANK RECEIPT VOUCHER
A6: Client Name: | E6: Prepared By:
A7: Year Ended: | E7: Reviewed By:
A8: Subject: | E8: Date:
A10: ='Cut off - Store'!A10:F10 -> OPENING TRANSACTIONS AS AT 01-07-2022
A12: Date | B12: Voucher # | C12: Receipt # | D12: Description | F12: Amount
A20: ='Cut off - Store'!A20:F20 -> CLOSING TRANSACTIONS AS AT 30-06-2023
A22: Date | B22: Voucher # | C22: Receipt # | D22: Description | F22: Amount
A30: ='Cut off - Store'!A30:F30 -> OPENING TRANSACTION - SUBSEQUENT AFTER 30-06-2023
A32: Date | B32: Voucher # | C32: Receipt # | D32: Description | F32: Amount
A40: CONCLUSION:

Sheet Cut off - CPV
A1: =Index!A1 -> ABC & Co.
A2: =Index!A2 -> (Chartered Accountants)
A4: CUT OFF PROCEDURES - CASH PAYMENT VOUCHER
A6: Client Name: | E6: Prepared By:
A7: Year Ended: | E7: Reviewed By:
A8: Subject: | E8: Date:
A10: ='Cut off - Store'!A10:F10 -> OPENING TRANSACTIONS AS AT 01-07-2022
A12: Date | B12: Voucher # | C12: Invoice # | D12: Description | F12: Amount
A20: ='Cut off - Store'!A20:F20 -> CLOSING TRANSACTIONS AS AT 30-06-2023
A22: Date | B22: Voucher # | C22: Invoice # | D22: Description | F22: Amount
A30: ='Cut off - Store'!A30:F30 -> OPENING TRANSACTION - SUBSEQUENT AFTER 30-06-2023
A32: Date | B32: Voucher # | C32: Invoice # | D32: Description | F32: Amount
A40: CONCLUSION:

Sheet Cut off - CRV
A1: =Index!A1 -> ABC & Co.
A2: =Index!A2 -> (Chartered Accountants)
A4: CUT OFF PROCEDURES - CASH RECEIPT VOUCHER
A6: Client Name: | E6: Prepared By:
A7: Year Ended: | E7: Reviewed By:
A8: Subject: | E8: Date:
A10: ='Cut off - Store'!A10:F10 -> OPENING TRANSACTIONS AS AT 01-07-2022
A12: Date | B12: Voucher # | C12: Invoice # | D12: Description | F12: Amount
A20: ='Cut off - Store'!A20:F20 -> CLOSING TRANSACTIONS AS AT 30-06-2023
A22: Date | B22: Voucher # | C22: Invoice # | D22: Description | F22: Amount
A30: ='Cut off - Store'!A30:F30 -> OPENING TRANSACTION - SUBSEQUENT AFTER 30-06-2023
A32: Date | B32: Voucher # | C32: Invoice # | D32: Description | F32: Amount
A40: CONCLUSION:
