Workbook

Sheet Index
B1: =UPPER("(Name of Firm)") -> (NAME OF FIRM) | F1: QM
B2: (CHARTERED ACCOUNTANTS)
B4: INDEX
B6: Sr. # | C6: Description | D6: W.P. Ref. | E6: Whether Placed in File | F6: Initials of Reviewer
B8: 1 | C8: Confirmation of understanding of ISQM | D8: =$F$1&"-0"&B8 -> QM-01
B10: =B8+1 -> 2 | C10: Consultation Agreement | D10: =$F$1&"-0"&B10 -> QM-02
B12: =B10+1 -> 3 | C12: Fit and Proper Form for the Firm as a Whole | D12: =$F$1&"-0"&B12 -> QM-03
B14: =B12+1 -> 4 | C14: Fit and Proper Form for Engagement Team | D14: =$F$1&"-0"&B14 -> QM-04
B16: =B14+1 -> 5 | C16: Competence Evaluation Form | D16: =$F$1&"-0"&B16 -> QM-05
B18: =B16+1 -> 6 | C18: Staff Compliance Confirmation Checklist for the Individuals | D18: =$F$1&"-0"&B18 -> QM-06
B20: =B18+1 -> 7 | C20: Engagement Quality Control Review | D20: =$F$1&"-0"&B20 -> QM-07
B22: =B20+1 -> 8 | C22: Reappointment / Continuance Assessment | D22: =$F$1&"-0"&B22 -> QM-08
B24: =B22+1 -> 9 | C24: New Client Acceptance Assessment | D24: =$F$1&"-0"&B24 -> QM-09
B26: =B24+1 -> 10 | C26: Independence Checklist - Engagement Wise | D26: =$F$1&"-"&B26 -> QM-10
B28: =B26+1 -> 11 | C28: Independence Register - Firm wide | D28: =$F$1&"-"&B28 -> QM-11
B30: =B28+1 -> 12 | C30: Complaints Form | D30: =$F$1&"-"&B30 -> QM-12
B32: =B30+1 -> 13 | C32: Trainee Admission Form | D32: =$F$1&"-"&B32 -> QM-13
B34: =B32+1 -> 14 | C34: Candidates Evaluation Form | D34: =$F$1&"-"&B34 -> QM-14
B36: =B34+1 -> 15 | C36: Appointment Letter | D36: =$F$1&"-"&B36 -> QM-15
B38: =B36+1 -> 16 | C38: Lecture Attendance & Minutes Summary | D38: =$F$1&"-"&B38 -> QM-16
B40: =B38+1 -> 17 | C40: Experience Letter | D40: =$F$1&"-"&B40 -> QM-17
B42: =B40+1 -> 18 | C42: Advance Request Form | D42: =$F$1&"-"&B42 -> QM-18
B44: =B42+1 -> 19 | C44: Leave Application Form | D44: =$F$1&"-"&B44 -> QM-19
B46: =B44+1 -> 20 | C46: Annual Survey Form | D46: =$F$1&"-"&B46 -> QM-20
B48: =B46+1 -> 21 | C48: Performance Feedback from Leadership | D48: =$F$1&"-"&B48 -> QM-21

Sheet Confirmation of Understanding
B1: =Index!B1 -> (NAME OF FIRM) | G1: =Index!D8 -> QM-01
B2: =Index!B2 -> (CHARTERED ACCOUNTANTS)
B4: =Index!C8 -> Confirmation of understanding of ISQM
B6: Sr. # | C6: Employee ID, If available | D6: Employee Name | E6: Position | F6: Signature | G6: Date
B8: =B7+1 -> 1
B9: =B8+1 -> 2
B10: =B9+1 -> 3
B11: =B10+1 -> 4
B12: =B11+1 -> 5
B13: =B12+1 -> 6
B14: =B13+1 -> 7
B15: =B14+1 -> 8
B16: =B15+1 -> 9
B17: =B16+1 -> 10
B18: =B17+1 -> 11
B19: =B18+1 -> 12
... B37: =B36+1 -> 30

Sheet Consultation
B1: =Index!B1 -> (NAME OF FIRM) | E1: =Index!D10 -> QM-02
B2: =Index!B2 -> (CHARTERED ACCOUNTANTS)
B4: =Index!C10 -> Consultation Agreement
B6: Name of Firm
B7: Address of Firm
B9: Dear Sir(s)
B11: This letter sets out the terms on which _____________ (I / we) agree to provide consultation services for your firm. ____________ (I / We) will provide your firm with consultation on ethical and audit related issues, where requested and possible.
B15: Agreement of independent consultant
B16: 1. _________ (I / We) confirm that assignments will only be completed where ______________ (I am / We are) independent.
B17: 2. _________ (I / We) confirm that assignments will only be completed where ______________ (I / We) have no conflict of interest.
B19: 3. _________ (I / We) confirm that any information obtained during the course of any consultation or review will be treated in confidence and no information will be divulged to any other party, without your prior written consent.
B22: 4. The work will be undertaken on the basis that no legal action or other claims will be made against __________ (me / us) by you in respect of any reviews conducted.
B25: Yours sincerely
B27: Signed by:
B30: _______________________________
... B55: Record of Consultation
B57: Client: | C57: _______________________
B58: Period: | C58: _______________________
B60: Problem to be considered:
B61: Name of consultant used and reason for selection:
B62: Actions discussed:
B63: Conclusion:
B65: Prepared By: | D65: Date:
B67: Reviewed By: | D67: Date:

Sheet Fit and Proper Firm
B1: =Index!B1 -> (NAME OF FIRM) | E1: =Index!D12 -> QM-03
B2: =Index!B2 -> (CHARTERED ACCOUNTANTS)
B4: =Index!C12 -> Fit and Proper Form for the Firm as a Whole
B6: Sr. # | C6: Issues | D6: Answer in Yes / No | E6: Details, if answer is Yes
B8: =B7+1 -> 1 | C8: In the last ten years, the firm has made any compromise or arrangement with its creditors, or otherwise failed to satisfy creditors in full. | D8: No
B9: =B8+1 -> 2 | C9: In the last five years, the firm has been the subject of any civil action relating to its professional or business activities which resulted in a finding against it by a court, or a settlement being agreed except as detailed below. | D9: No
B10: =B9+1 -> 3 | C10: In the last ten years, the firm has been refused or restricted in the right to carry on any trade, business or profession for which a specific licence, registration or other authority is required | D10: No
B11: =B10+1 -> 4 | C11: In the last ten years, the firm has been refused entry to any professional body or trade association, or decided not to continue with an application; | D11: No
B12: =B11+1 -> 5 | C12: In the last ten years, the firm has been reprimanded, warned about future conduct, disciplined or publicly criticised by any professional or regulatory body; | D12: No
B13: =B12+1 -> 6 | C13: In the last ten years, the firm has been made the subject of a court order at the instigation of any professional or regulatory body; or | D13: No
B14: =B13+1 -> 7 | C14: In the last ten years, the firm has been investigated on allegations of misconduct or malpractice in connection with its professional or business activities which resulted in a formal complaint being proved but no disciplinary order being made; | D14: No
B17: Signed by:
B21: ____________________________
B22: Partner In-charge of Compliance

Sheet Fit and Proper - Engagement
B1: =Index!B1 -> (NAME OF FIRM) | E1: =Index!D14 -> QM-04
B2: =Index!B2 -> (CHARTERED ACCOUNTANTS)
B4: =Index!C14 -> Fit and Proper Form for Engagement Team
B6: Client:
B8: Date:
B10: Sr. # | C10: Issues | D10: Answer in Yes / No | E10: Comments, if answer is No
B12: =B11+1 -> 1 | C12: Does the team have sufficient practical experience to enable them to undertake this assignment? | D12: Yes
B13: =B12+1 -> 2 | C13: Does the team have sufficient understanding of professional standards and regulatory and legal requirements? | D13: Yes
B14: =B13+1 -> 3 | C14: Does the team have sufficient up to date technical knowledge including knowledge of relevant information technology? | D14: Yes
B15: =B14+1 -> 4 | C15: Does the team have sufficient knowledge of the business and of the industry in which the client operates? | D15: Yes
B16: =B15+1 -> 5 | C16: Does the team have sufficient members who are able to apply sound professional judgment? | D16: Yes
B17: =B16+1 -> 6 | C17: Does the team have sufficient knowledge of the firm's quality control policies and procedures? | D17: Yes
B20: Conclusion
B26: Signed by:
B29: ___________________________
B30: Engagement Partner

Sheet Competence Evaluation
B1: =Index!B1 -> (NAME OF FIRM) | E1: =Index!D16 -> QM-05
B2: =Index!B2 -> (CHARTERED ACCOUNTANTS)
B4: =Index!C16 -> Competence Evaluation Form
B6: Client:
B8: Date:
B10: Sr. # | C10: Competence to Perform the Engagement | D10: Response
B12: =B11+1 -> 1 | C12: Indicate the number of years of experience the engagement partner has in the entity’s industry | D12: The engagement partner has 20+ years of experience of working with clients of this industry
B13: =B12+1 -> 2 | C13: Is this engagement subject to partner rotation requirements? | D13: The engagement partner is subject to rotation after every 5 or 7 years as per ICAP Code of Ethics. No, the engagement partner is not subject to rotation as per ICAP Code of Ethics.
B14: =B13+1 -> 3 | C14: Indicate the number of years of experience the engagement manager has in the entity’s industry. | D14: The engagement manager has 5+ years of experience of working with clients of this industry.
B15: =B14+1 -> 4 | C15: Evaluate the Engagement level resource plan to ensure resources are sufficient to perform the engagement. | D15: The firm has sufficient resources to perform the engagement.
B18: Sr. # | C18: Issues | D18: Answer in Yes / No | E18: Response, if answer is Yes
B20: =B19+1 -> 1 | C20: Does the entity have operations in any of the following high risk industries or portfolios? • Banks, financial institutions • Insurance providers • Mutual funds • Gambling/gaming • Brokers/dealers • Real estate/construction • Leasing • Public sector not-for-profit • High litigation industries • Software development • Sport franchises • Businesses with going concern issues | D20: No
B21: =B20+1 -> 2 | C21: Does the entity recognize revenue applying complex or evolving accounting conventions? | D21: No
B22: =B21+1 -> 3 | C22: Will the engagement require the use of work of experts? | D22: No | E22: In case, there is Gratuity or Revaluation. In that case, expert is required
B24: Sr. # | C24: Issues | D24: Answer in Yes / No | E24: Response, if answer is Yes
B26: =B22+1 -> 4 | C26: Are there any concerns regarding the availability of professional staff to enable completion of the engagement to a both a quality standard and in a timely manner? | D26: No
B27: =B26+1 -> 5 | C27: Does the entity have significant activities related to any of the following areas: • Acquisition accounting • Reorganization • Restructuring charges • Self-insurance • Use of derivatives • Debt covenants • Other | D27: No
B28: =B27+1 -> 6 | C28: Are there any concerns regarding the partner and staff having sufficient knowledge and experience for the engagement? | D28: No
B29: =B28+1 -> 7 | C29: Are there any matters related to staffing the engagement which would indicate that the engagement should not be accepted or why such acceptance needs to be considered by a second partner or head of specialization? | D29: No
B30: =B29+1 -> 8 | C30: Are any special licenses or permits or approvals required for our staff to carry-out the engagement in the jurisdiction where the work will be performed? | D30: No
C32: Overall Assessment
B33: =B30+1 -> 9 | C33: Does the engagement team, including appropriate industry and specialty experts who will be part of the team, have the relevant experience and competence and sufficient available time to: • Address the primary and other industries noted above? • Address any risks or issues noted in the above? • Reduce any competency risks associated with the engagement to an acceptable level? | D33: Yes | E33: The engagement team is sufficiently qualified and has the necessary skills and competence to perform the audit.
B36: Signed by:
B39: ___________________________
B40: Engagement Partner

Sheet Staff Compliance Confirmation
B1: =Index!B1 -> (NAME OF FIRM) | E1: =Index!D18 -> QM-06
B2: =Index!B2 -> (CHARTERED ACCOUNTANTS)
B4: =Index!C18 -> Staff Compliance Confirmation Checklist for the Individuals
B6: Name:
B8: Date:
B11: Independence
B12: In accordance with the policy of this firm, all partners, professional staff and others involved in or otherwise connected with audit work must complete and sign a statement of independence as a condition of employment.
B15: Sr. # | C15: Issues | D15: Answer in Yes / No | E15: Details, if applicable
B17: =B16+1 -> 1 | C17: I was in compliance with Firm’s independence policies as outlined in the Code of Ethics for Chartered Accountants and the Companies Act, 2017 regarding any direct or material indirect financial interest in an audit client of the firm during the Confirmation Period. | D17: Yes
B18: =B17+1 -> 2 | C18: I was in compliance with Firm’s independence policies as outlined in the Code of Ethics for Chartered Accountants and the Companies Act, 2017 regarding business relationships with an audit client of the firm during the Confirmation Period. | D18: Yes
B19: =B18+1 -> 3 | C19: I was in compliance with Firm’s independence policies as outlined in the Code of Ethics for Chartered Accountants and the Companies Act, 2017 regarding Loans from an audit client of the firm during the Confirmation Period. | D19: Yes
B20: =B19+1 -> 4 | C20: I was in compliance with Firm’s independence policies as outlined in the Code of Ethics for Chartered Accountants and the Companies Act, 2017 regarding Credit facility from an audit client of the firm during the Confirmation Period. | D20: Yes
B21: =B20+1 -> 5 | C21: I was in compliance with Firm’s independence policies as outlined in the Code of Ethics for Chartered Accountants and the Companies Act, 2017 regarding Savings / Deposits Accounts with an audit client of the firm during the Confirmation Period. | D21: Yes
B22: Sr. # | C22: Issues | D22: Answer in Yes / No | E22: Details, if applicable
B24: =B21+1 -> 6 | C24: I was in compliance with Firm’s independence policies as outlined in the Code of Ethics for Chartered Accountants and the Companies Act, 2017 regarding Employment of family members and personal relationships with an audit client of the firm during the Confirmation Period. | D24: Yes
B25: =B24+1 -> 7 | C25: I was in compliance with Firm’s independence policies as outlined in the Code of Ethics for Chartered Accountants and the Companies Act, 2017 regarding Employment with an audit client of the firm in a prohibited role during the Confirmation Period. | D25: Yes
B26: =B25+1 -> 8 | C26: I was in compliance with Firm’s independence policies as outlined in the Code of Ethics for Chartered Accountants and the Companies Act, 2017 regarding Recent Service with an audit client of the firm during the Last Two Years. | D26: Yes
B27: =B26+1 -> 9 | C27: I was in compliance with Firm’s independence policies as outlined in the Code of Ethics for Chartered Accountants and the Companies Act, 2017 regarding purchase of goods and services during the Confirmation Period and didn’t accept any material goods or services on favourable terms, or received undue hospitality from any audit client? | D27: Yes
B30: Outside business interests
B31: The firm must be independent in its dealings with business clients. Please list below any business interests, directorships, etc. that you have.
B33: Sr. # | C33: Issues | D33: Answer in Yes / No | E33: Details, if answer is Yes
B35: =B34+1 -> 1 | C35: Business Interest | D35: No
B36: =B35+1 -> 2 | C36: Directorship | D36: No
B37: =B36+1 -> 3 | C37: Other | D37: No
B42: Confidentiality
B43: In accordance with the policy of the firm, all partners, staff, sub-contractors and consultants involved in or connected with audit work, must complete and sign a statement of confidentiality as a condition of employment. Your attention is drawn to the need for confidentiality on all audit assignments, in particular: - working papers must always be kept secure so that unauthorised access is not gained by either the client’s staff or third parties; - the firm’s audit procedures should not be disclosed to third parties without proper approval from the partner in charge; - information about the client should not be disclosed to either the client’s staff or third parties without proper approval from the partner in charge or the client. Breach of the rules regarding confidential information will be considered as gross misconduct and normally, subject to investigation, will result in instant dismissal and, in certain circumstances, legal action.
B52: Sr. # | C52: Queries to be replied | D52: Answer in Yes / No | E52: Details, if applicable
B54: =B53+1 -> 1 | C54: In the last ten years, has any court, given any judgement against you about a debt? | D54: No
B55: =B54+1 -> 2 | C55: In the last ten years, has any court, given any judgement against you about a debt? | D55: No
B56: =B55+1 -> 3 | C56: Have you ever been declared bankrupt or been the subject of a bankruptcy court order, or has a bankruptcy petition ever been served on you? | D56: No
B57: =B56+1 -> 4 | C57: Have you ever signed a trust deed for a creditor, made an assignment for the benefit of creditors, or made any arrangements for the payment of a composition to creditors? | D57: No
B58: =B57+1 -> 5 | C58: Have you at any time pleaded guilty to or been found guilty of any offence? If so, give details, at the end of this form, of the court which convicted you, the offence, and the penalty imposed and date of conviction. | D58: No
B59: =B58+1 -> 6 | C59: In the last five years have you, in Pakistan or elsewhere, been the subject of any civil action relating to your professional or business activities which has resulted in a finding against you by a court or a settlement being agreed? | D59: No
B60: =B59+1 -> 7 | C60: Have you ever been disqualified by a court from being a director, or from acting in the management or conduct of the affairs of any company? | D60: No
B61: =B60+1 -> 8 | C61: Have you ever been refused the right or been restricted in the right to carry on any trade, business or profession for which a specific license, registration or other authority is required? | D61: No
B62: Sr. # | C62: Queries to be replied | D62: Answer in Yes / No | E62: Details, if applicable
B64: =B61+1 -> 9 | C64: Have you ever been investigated about allegations of misconduct or malpractice in connection with your professional activities which resulted in a formal complaint being proved but no disciplinary order being made? | D64: No
B65: =B64+1 -> 10 | C65: Have you ever been the subject of disciplinary procedures by a professional body or employer resulting in a finding against you? | D65: No
B66: =B65+1 -> 11 | C66: Have you ever been reprimanded, excluded, disciplined or publicly criticised by any professional body which you belong or have belonged to? | D66: No
B67: =B66+1 -> 12 | C67: Have you ever been refused entry to or excluded from membership of any profession or vocation? | D67: No
...

Sheet EQCR
B1: =Index!B1 -> (NAME OF FIRM) | D1: =Index!D20 -> QM-07
B2: =Index!B2 -> (CHARTERED ACCOUNTANTS)
B4: =Index!C20 -> Engagement Quality Control Review
B6: General Information
B8: Questions | C8: Replies / Comments
B10: General Information
B12: Name of Engagement Partner
B14: Name of Reviewer
B16: Number of files Reviewed
B18: Detailed Information
B19: Have all the people detailed in Engagement Team List confirmed their independence on the assignments being reviewed and, where appropriate, signed the agreement for consultation purposes?
B20: Has the scope of the review been agreed?
B21: Were the findings in line with the review?
B22: Does the sample of files selected give adequate coverage of high risk and special category audits?
B25: Observations / Deficiencies Found
B27: Observation / Deficiency | C27: Replies / Comments by Engagement Team
B37: Signed By:
B40: ___________________ | C40: ___________________
B41: Engagement Partner | C41: Engagement Reviewer
B43: Date: ____________________ | C43: Date: ____________________

Sheet Continuance Assessment
B1: =Index!B1 -> (NAME OF FIRM) | D1: =Index!D22 -> QM-08
B2: =Index!B2 -> (CHARTERED ACCOUNTANTS)
B4: =Index!C22 -> Reappointment / Continuance Assessment
B6: Client Information
B8: Questions | C8: Replies / Comments
B10: General Information
B11: Full / Legal Name of the Entity
B12: Entity's Principal Address
B14: Detailed Information
B15: Name of Ultimate Parent
B16: Major Shareholder Section | C16: Name of Major Shareholders: 1. 2. 3.
B17: Principal Officer Section | C17: Number of Principal Officers: Names and Designations: 1. 2. 3.
B18: What is the sophistication and experience of the client with regard to the service to be provided?
B19: Is this a Public Interest Entity (PIC)?
B20: Is the industry in which the Entity operates considered higher risk?
B21: Is the Entity part of a complex legal ownership structure that cannot be justified?
B22: Is the Entity's business or business model subject to significant uncertainties?
B25: Ethical consideration
B27: Questions | C27: Replies / Comments
B29: Are we satisfied that there are no threats to objectivity or independence?
B30: Does the firm have adequate knowledge and resources?
B31: Have any issues arisen in respect of the firm’s competence during the audit?
B32: Do we have reason to believe that the audit will not make an adequate recovery in future?
B33: Questions | C33: Replies / Comments
B35: Are we satisfied that there are no other ethical reasons why the firm should not accept the client?
B36: Are there any other issues that should be taken in to consideration when determining whether reappointment should be sought?
B39: Is Engagement Quality Control Reviewer Required? If “Yes” Please specify name:
B42: Signed By:
B45: ___________________
B46: Engagement Partner
B48: Date: ____________________

Sheet New Clients Checklist
B1: =Index!B1 -> (NAME OF FIRM) | D1: =Index!D24 -> QM-09
B2: =Index!B2 -> (CHARTERED ACCOUNTANTS)
B4: =Index!C24 -> New Client Acceptance Assessment
B6: Client Information
B8: Questions | C8: Replies / Comments
B10: General Information
B11: Full / Legal Name of the Entity
B12: Entity's Principal Address
B14: Detailed Information
B15: Name of Ultimate Parent
B16: Major Shareholder Section | C16: Name of Major Shareholders: 1. 2. 3.
B17: Principal Officer Section | C17: Number of Principal Officers: Names and Designations: 1. 2. 3.
B18: Industry that most closely describes the primary business of the Entity.
B19: Entity's Main Business (Provide Description)
B20: Has firm previously declined to accept this Entity?
B21: Is the Entity listed or planning to list its securities in any stock exchange in the next twelve months?
B22: Does the Entity have control or have significant influence over another public company?
B23: Does another public company have control or significant influence over the Entity?
B24: Is this a Public Interest Entity (PIC)?
B25: Is the industry in which the Entity operates considered higher risk?
B26: Is the Entity part of a complex legal ownership structure that cannot be justified?
B27: Is the Entity's business or business model subject to significant uncertainties?
B34: Ethical consideration
B36: Questions | C36: Replies / Comments
B38: Are we satisfied that there are no threats to objectivity or independence?
B39: Does the firm have adequate knowledge and resources?
B40: Can we confirm that acceptance of the client will not create a conflict of interest?
B41: Are we satisfied that the acceptance of the appointment would not have an adverse effect on the reputation of the practice?
B42: Are we satisfied that there are no other ethical reasons why the firm should not accept the client?
B43: Are we satisfied that there are no other reasons why we would not wish to act for the client (for example, financial difficulties or litigation)?
B46: Change in appointment
B48: Questions | C48: Replies / Comments
B50: Has the previous auditor been contacted in accordance with the Institute’s regulations?
B51: Does any information contained in the reply impact the client acceptance?
B52: Have the statutory resignation procedures been complied with?
B53: Note
B54: If no reply is received from the existing auditor, send a follow-up request by recorded or registered delivery, stating a deadline after which it will be assumed that there are no professional reasons why the appointment should be declined.
B55: If no reply is received from previous auditor, obtain proof of resignation or valid removal from office.
B63: Money laundering
B65: Questions | C65: Replies / Comments
...

Sheet Independence Checklist
B1: =Index!B1 -> (NAME OF FIRM) | F1: =Index!D26 -> QM-10
B2: =Index!B2 -> (CHARTERED ACCOUNTANTS)
B4: Client:
B5: Date:
B6: Completed by:
B7: Reviewed by:
B9: =Index!C26 -> Independence Checklist - Engagement Wise
B11: Entity type:
B12: Audit Fee:
B13: Other Services provided:
B15: Audit partner
B16: No. of years in role
B18: Audit manager
B19: No. of years in role
B21: Independence issues
B23: Sr. # | C23: Issues | D23: Answer in Yes / No | E23: Details, if answer is Yes | F23: Proposed Action
B25: =B24+1 -> 1 | C25: Are there any issues that could result in a self interest threat?
B26: =B25+1 -> 2 | C26: Are there any issues that could result in a self review threat?
B27: =B26+1 -> 3 | C27: Are there any issues that could result in an advocacy threat?
B28: =B27+1 -> 4 | C28: Are there any issues that could result in a familiarity or trust threat?
B29: =B28+1 -> 5 | C29: Are there any issues that could result in an intimidation threat?
B30: =B29+1 -> 6 | C30: Are there any other reasons why we may not wish to act for this client?
B32: Conclusion by Engagement Partner | F32: Date:
B35: Conclusion by Managing Partner, if any | F35: Date:

Sheet Independence Register
B1: =Index!B1 -> (NAME OF FIRM) | F1: =Index!D28 -> QM-11
B2: =Index!B2 -> (CHARTERED ACCOUNTANTS)
B4: =Index!C28 -> Independence Register - Firm wide
B6: Sr. # | C6: Issues | D6: Answer in Yes / No | E6: Details, if answer is Yes | F6: Proposed Action
B8: =B7+1 -> 1 | C8: Are there any issues that could result in a self interest threat?
B9: =B8+1 -> 2 | C9: Are there any issues that could result in a self review threat?
B10: =B9+1 -> 3 | C10: Are there any issues that could result in an advocacy threat?
B11: =B10+1 -> 4 | C11: Are there any issues that could result in a familiarity or trust threat?
B12: =B11+1 -> 5 | C12: Are there any issues that could result in an intimidation threat?
B13: =B12+1 -> 6 | C13: Are there any other reasons why we may not wish to act for this client?
B15: Conclusion by Engagement Partner | F15: Date:
B19: Conclusion by Second Partner, if any | F19: Date:

Sheet Complaints Form
B1: =Index!B1 -> (NAME OF FIRM) | D1: =Index!D30 -> QM-12
B2: =Index!B2 -> (CHARTERED ACCOUNTANTS)
B4: Client:
B5: Date:
B6: Engagement Partner:
B7: Partner responsible for dealing with the complaint:
B10: =Index!C30 -> Complaints Form
B13: Description of Complaint
B15: Nature of the complaint:
B16: Detail below the results of the investigation into the complaint:
B17: Detail below the action that needs to be taken:
B18: Detail below the clients response:
B19: Are there any issues that need to be communicated to staff? If so, state how this has been dealt with:
D24: Signed by: Partner responsible for dealing with the complaint

Sheet Lecture Attendance & Minutes
B1: =Index!B1 -> (NAME OF FIRM) | F1: =Index!D38 -> QM-16
B2: =Index!B2 -> (CHARTERED ACCOUNTANTS)
B4: =Index!C38 -> Lecture Attendance & Minutes Summary
B6: Lecture Summary | F6: Lecture Minutes
B8: Topic
B10: Delivered By:
B12: Total Attendance
B14: Date
B16: Attendance
B18: Sr. # | C18: Name | D18: Signature

Sheet Advance Request Form
B1: =Index!B1 -> (NAME OF FIRM) | I1: =Index!D42 -> QM-18
B2: =Index!B2 -> (CHARTERED ACCOUNTANTS)
B5: Advance Request Form
B8: Name
B10: Position
B13: Amount of Advance
B15: Purpose of Advance
B17: Date of Request
B21: Description of Matter:
B35: Prepared By | E35: Authorized By | H35: Approved By

Sheet Leave Application Form
B1: =Index!B1 -> (NAME OF FIRM) | I1: =Index!D44 -> QM-19
B2: =Index!B2 -> (CHARTERED ACCOUNTANTS)
B5: =Index!C44 -> Leave Application Form
B8: Name
B10: Position
B12: Date of Joining
B14: Period Served with Firm
B17: Leave Entitlement by the Institute
B19: Already availed (excluding applied)
B21: Balance Available
B24: Purpose of Leave
B26: Papers to be Attempted
B28: Period of Leave (From - To)
B30: Number of Days
B34: Manager's Comments:
B48: Applicant's Signature | E48: Manager's Signature | H48: Partner's Signature
